Workbook

Sheet 提出物チェックリスト
A2: 自主点検 提出物チェックリスト（構成単位版）
A3: ■ 会社名: ________________________ ■ 実施期: ______________ ■ サイクル (年度末 / 四半期): __________ ■ 記入者: ________________________
A4: 【凡例】 ☑提出 → □ を記入 / 対象外・未実施 → 「該当なし」に □ 記入し、理由を記述のうえ提出可。全行チェックは必須ではありません。
A6: No | B6: 項目No | C6: 点検項目名 | D6: 提出物名 | E6: 提出物詳細 | F6: 区分 | G6: 提出区分 | H6: 適用の目安 （条件付き・代替・排他の場合） | I6: 年度末 | J6: 四半期 | K6: ☑提出 | L6: 該当なし | M6: 非該当・未提出の理由 | N6: 格納先フォルダパス | O6: 一次ソース | P6: 備考
A7: 1 | B7: 1 | C7: 売掛金の残高確認 | D7: 残高確認状の回収結果・差異調整結果 | F7: ①成果物本体 | G7: 必須 | I7: ○ | K7: □ | L7: □ | N7: 01_監査対応/[会社名]/05_自主点検成果物/01_残高確認状 | O7: input/01_監査対応_自主点検成果物_ファイルリスト_filtered.xlsx（構成単位・2026年3月期）
A8: 2 | B8: 1 | C8: 売掛金の残高確認 | D8: 代替手続実施結果 | E8: 代替手続チェックリスト・入金消込管理表の検証資料 | F8: ①成果物本体 | G8: 条件付き | H8: 確認状を回収できない/発送しない相手先(個人・官公庁等)がある場合 | I8: ○ | K8: □ | L8: □ | N8: 01_監査対応/[会社名]/05_自主点検成果物/01_残高確認状 | O8: input/01_監査対応_自主点検成果物_ファイルリスト_filtered.xlsx（構成単位・2026年3月期）
A9: 3 | B9: 1 | C9: 売掛金の残高確認 | D9: 追加サンプリング結果 | F9: ②根拠資料 | G9: 条件付き | H9: 2026年6月以降入金予定の3月末売掛金残高が閾値以上 | I9: ○ | K9: □ | L9: □ | N9: 01_監査対応/[会社名]/05_自主点検成果物/01_残高確認状 | O9: input/01_監査対応_自主点検成果物_ファイルリスト_filtered.xlsx（構成単位・2026年3月期）
A10: 4 | B10: 1 | C10: 売掛金の残高確認 | D10: 売掛金明細 | E10: 2026年3月末 | F10: ③共通添付 | G10: 必須 | I10: ○ | K10: □ | L10: □ | N10: 01_監査対応/[会社名]/05_自主点検成果物/01_残高確認状 | O10: input/01_監査対応_自主点検成果物_ファイルリスト_filtered.xlsx（構成単位・2026年3月期）
A11: 5 | B11: 1 | C11: 売掛金の残高確認 | D11: 試算表＋連結PKGまでの調整 | E11: 3月末 | F11: ③共通添付 | G11: 必須 | I11: ○ | K11: □ | L11: □ | N11: 01_監査対応/[会社名]/05_自主点検成果物/01_残高確認状 | O11: input/01_監査対応_自主点検成果物_ファイルリスト_filtered.xlsx（構成単位・2026年3月期）
A12: 6 | B12: 2 | C12: 在庫の実地棚卸 | D12: 実地棚卸の結果 | E12: 別途ガイダンスに従い提出 | F12: ①成果物本体 | G12: 必須 | I12: ○ | K12: □ | L12: □ | N12: 01_監査対応/[会社名]/05_自主点検成果物/02_在庫の実地棚卸 | O12: input/01_監査対応_自主点検成果物_ファイルリスト_filtered.xlsx（構成単位・2026年3月期）
A13: 7 | B13: 2 | C13: 在庫の実地棚卸 | D13: 預り売上に関する親会社への情報・検討内容 | F13: ①成果物本体 | G13: 条件付き | H13: 預り売上(請求済未出荷)を計上している場合(原則禁止) | I13: ○ | K13: □ | L13: □ | N13: 01_監査対応/[会社名]/05_自主点検成果物/02_在庫の実地棚卸 | O13: input/01_監査対応_自主点検成果物_ファイルリスト_filtered.xlsx（構成単位・2026年3月期）
A14: 8 | B14: 3 | C14: 固定資産の実査 | D14: 固定資産実査報告書 | E14: 確定版:エクセル＋部署長検印済PDF | F14: ①成果物本体 | G14: 必須 | I14: ○ | K14: □ | L14: □ | N14: 01_監査対応/[会社名]/05_自主点検成果物/03_固定資産実査 | O14: input/01_監査対応_自主点検成果物_ファイルリスト_filtered.xlsx（構成単位・2026年3月期）
A15: 9 | B15: 3 | C15: 固定資産の実査 | D15: 現物照合の写真 | F15: ②根拠資料 | G15: 必須 | I15: ○ | K15: □ | L15: □ | N15: 01_監査対応/[会社名]/05_自主点検成果物/03_固定資産実査 | O15: input/01_監査対応_自主点検成果物_ファイルリスト_filtered.xlsx（構成単位・2026年3月期）
A16: 10 | B16: 3 | C16: 固定資産の実査 | D16: 代替証跡 | E16: 登記簿・リース契約書・使用実績資料等 | F16: ②根拠資料 | G16: 代替 | H16: 現物カウントが困難な資産がある場合 | I16: ○ | K16: □ | L16: □ | N16: 01_監査対応/[会社名]/05_自主点検成果物/03_固定資産実査 | O16: input/01_監査対応_自主点検成果物_ファイルリスト_filtered.xlsx（構成単位・2026年3月期）
A17: 11 | B17: 3 | C17: 固定資産の実査 | D17: 固定資産訂正仕訳が必要な資産の報告書 | F17: ①成果物本体 | G17: 条件付き | H17: 現物照合で訂正(除却漏れ・資産性等)が発覚した場合 | I17: ○ | K17: □ | L17: □ | N17: 01_監査対応/[会社名]/05_自主点検成果物/03_固定資産実査 | O17: input/01_監査対応_自主点検成果物_ファイルリスト_filtered.xlsx（構成単位・2026年3月期）
A18: 12 | B18: 3 | C18: 固定資産の実査 | D18: 修正仕訳のエビデンス | E18: Proplusモニターシート・Biz∫仕訳 | F18: ②根拠資料 | G18: 条件付き | H18: 修正仕訳を起票した場合 | I18: ○ | K18: □ | L18: □ | N18: 01_監査対応/[会社名]/05_自主点検成果物/03_固定資産実査 | O18: input/01_監査対応_自主点検成果物_ファイルリスト_filtered.xlsx（構成単位・2026年3月期）
A19: 13 | B19: 3 | C19: 固定資産の実査 | D19: 独立立会人による実査立会結果 | F19: ①成果物本体 | G19: 条件付き | H19: 第2線立会対象(規模条件) | I19: ○ | K19: □ | L19: □ | N19: 01_監査対応/[会社名]/05_自主点検成果物/03_固定資産実査 | O19: input/01_監査対応_自主点検成果物_ファイルリスト_filtered.xlsx（構成単位・2026年3月期）
A20: 14 | B20: 4 | C20: 滞留債権の分析 | D20: 期末滞留債権一覧 | E20: 回収遅延理由・最新回収予定日 | F20: ①成果物本体 | G20: 必須 | I20: ○ | J20: ○ | K20: □ | L20: □ | N20: 01_監査対応/[会社名]/05_自主点検成果物/04_滞留債権 | O20: input/01_監査対応_自主点検成果物_ファイルリスト_filtered.xlsx（構成単位・2026年3月期）
A21: 15 | B21: 4 | C21: 滞留債権の分析 | D21: 売掛金明細・試算表の一致 | E21: データソース・抽出条件 | F21: ③共通添付 | G21: 必須 | I21: ○ | J21: ○ | K21: □ | L21: □ | N21: 01_監査対応/[会社名]/05_自主点検成果物/04_滞留債権 | O21: input/01_監査対応_自主点検成果物_ファイルリスト_filtered.xlsx（構成単位・2026年3月期）
A22: 16 | B22: 4 | C22: 滞留債権の分析 | D22: 回収遅延理由の承認証跡 | F22: ②根拠資料 | G22: 代替 | H22: 部門責任者等の承認(チェックリスト承認で代替可) | I22: ○ | J22: ○ | K22: □ | L22: □ | N22: 01_監査対応/[会社名]/05_自主点検成果物/04_滞留債権 | O22: input/01_監査対応_自主点検成果物_ファイルリスト_filtered.xlsx（構成単位・2026年3月期）
A23: 17 | B23: 4 | C23: 滞留債権の分析 | D23: 外部証憑 | E23: 契約書・注文書・納品書 等 | F23: ②根拠資料 | G23: 条件付き | H23: 回収遅延理由が合理的でない債権がある場合 | I23: ○ | J23: ○ | K23: □ | L23: □ | N23: 01_監査対応/[会社名]/05_自主点検成果物/04_滞留債権 | O23: input/01_監査対応_自主点検成果物_ファイルリスト_filtered.xlsx（構成単位・2026年3月期）
A24: 18 | B24: 5 | C24: 異常取引の分析 | D24: 年間取引データ | E24: 取引先別・案件別ソート,マイナス理由記載 | F24: ①成果物本体 | G24: 必須 | I24: ○ | J24: ○ | K24: □ | L24: □ | N24: 01_監査対応/[会社名]/05_自主点検成果物/05_売上マイナスデータ・取り消し仕訳 | O24: input/01_監査対応_自主点検成果物_ファイルリスト_filtered.xlsx（構成単位・2026年3月期）
A25: 19 | B25: 5 | C25: 異常取引の分析 | D25: 翌期4月分の二次提出データ | F25: ①成果物本体 | G25: 必須 | I25: ○ | J25: ○ | K25: □ | L25: □ | N25: 01_監査対応/[会社名]/05_自主点検成果物/05_売上マイナスデータ・取り消し仕訳 | O25: input/01_監査対応_自主点検成果物_ファイルリスト_filtered.xlsx（構成単位・2026年3月期）
A26: 20 | B26: 5 | C26: 異常取引の分析 | D26: データソース・抽出条件 | E26: 全明細と試算表の一致 | F26: ③共通添付 | G26: 必須 | I26: ○ | J26: ○ | K26: □ | L26: □ | N26: 01_監査対応/[会社名]/05_自主点検成果物/05_売上マイナスデータ・取り消し仕訳 | O26: input/01_監査対応_自主点検成果物_ファイルリスト_filtered.xlsx（構成単位・2026年3月期）
A27: 21 | B27: 5 | C27: 異常取引の分析 | D27: マイナス取引の根拠資料 | E27: ①計上妥当②取消妥当 | F27: ②根拠資料 | G27: 条件付き | H27: 2次レビューで確認が必要な取引 | I27: ○ | J27: ○ | K27: □ | L27: □ | N27: 01_監査対応/[会社名]/05_自主点検成果物/05_売上マイナスデータ・取り消し仕訳 | O27: input/01_監査対応_自主点検成果物_ファイルリスト_filtered.xlsx（構成単位・2026年3月期）
A28: 22 | B28: 6 | C28: 売上の期末変動分析 | D28: 月次の売上・粗利推移データ | E28: グラフ・増減分析コメント | F28: ①成果物本体 | G28: 必須 | I28: ○ | J28: ○ | K28: □ | L28: □ | N28: 01_監査対応/[会社名]/05_自主点検成果物/06_売上・粗利月次推移分析 | O28: input/01_監査対応_自主点検成果物_ファイルリスト_filtered.xlsx（構成単位・2026年3月期）
A29: 23 | B29: 6 | C29: 売上の期末変動分析 | D29: データソース・抽出条件 | E29: 試算表との一致 | F29: ③共通添付 | G29: 必須 | I29: ○ | J29: ○ | K29: □ | L29: □ | N29: 01_監査対応/[会社名]/05_自主点検成果物/06_売上・粗利月次推移分析 | O29: input/01_監査対応_自主点検成果物_ファイルリスト_filtered.xlsx（構成単位・2026年3月期）
A30: 24 | B30: 6 | C30: 売上の期末変動分析 | D30: 増減要因の根拠証憑 | F30: ②根拠資料 | G30: 条件付き | H30: 四半期末月に上昇傾向・重要変動がある場合 | I30: ○ | J30: ○ | K30: □ | L30: □ | N30: 01_監査対応/[会社名]/05_自主点検成果物/06_売上・粗利月次推移分析 | O30: input/01_監査対応_自主点検成果物_ファイルリスト_filtered.xlsx（構成単位・2026年3月期）
A31: 25 | B31: 7 | C31: 収益認識アンケート（証憑提出含む） | D31: 収益認識アンケート回答 | E31: SPファイル直接更新/メール返信 | F31: ①成果物本体 | G31: 必須 | I31: ○ | J31: ○ | K31: □ | L31: □ | N31: 01_監査対応/[会社名]/05_自主点検成果物/07_収益認識アンケート | O31: input/01_監査対応_自主点検成果物_ファイルリスト_filtered.xlsx（構成単位・2026年3月期）
A32: 26 | B32: 7 | C32: 収益認識アンケート（証憑提出含む） | D32: 契約書PDF | E32: 取引基本契約書等 | F32: ②根拠資料 | G32: 条件付き | H32: 年間売上金額が閾値以上の取引(半期提出済は再提出不要) | I32: ○ | J32: ○ | K32: □ | L32: □ | N32: 01_監査対応/[会社名]/05_自主点検成果物/07_収益認識アンケート | O32: input/01_監査対応_自主点検成果物_ファイルリスト_filtered.xlsx（構成単位・2026年3月期）
A33: 27 | B33: 7 | C33: 収益認識アンケート（証憑提出含む） | D33: 当期の売上明細データ | E33: 試算表との一致を事前確認 | F33: ③共通添付 | G33: 必須 | I33: ○ | J33: ○ | K33: □ | L33: □ | N33: 01_監査対応/[会社名]/05_自主点検成果物/07_収益認識アンケート | O33: input/01_監査対応_自主点検成果物_ファイルリスト_filtered.xlsx（構成単位・2026年3月期）
A34: 28 | B34: 8 | C34: 売上のカットオフテスト | D34: 売上明細データ | E34: 検証結果コメント付 | F34: ①成果物本体 | G34: 必須 | I34: ○ | J34: ○ | K34: □ | L34: □ | N34: 01_監査対応/[会社名]/05_自主点検成果物/08_売上明細データ | O34: input/01_監査対応_自主点検成果物_ファイルリスト_filtered.xlsx（構成単位・2026年3月期）
A35: 29 | B35: 8 | C35: 売上のカットオフテスト | D35: データソース・抽出条件 | E35: 3月単月の試算表一致 | F35: ③共通添付 | G35: 必須 | I35: ○ | J35: ○ | K35: □ | L35: □ | N35: 01_監査対応/[会社名]/05_自主点検成果物/08_売上明細データ | O35: input/01_監査対応_自主点検成果物_ファイルリスト_filtered.xlsx（構成単位・2026年3月期）
A36: 30 | B36: 8 | C36: 売上のカットオフテスト | D36: 収益認識の根拠資料 | F36: ②根拠資料 | G36: 条件付き | H36: 一定金額以上の取引に限る | I36: ○ | J36: ○ | K36: □ | L36: □ | N36: 01_監査対応/[会社名]/05_自主点検成果物/08_売上明細データ | O36: input/01_監査対応_自主点検成果物_ファイルリスト_filtered.xlsx（構成単位・2026年3月期）
A37: 31 | B37: 9 | C37: 長期請負工事案件の洗い出し | D37: 進行基準適用案件リスト | E37: 履行義務毎の判断根拠 | F37: ①成果物本体 | G37: 必須 | I37: ○ | J37: ○ | K37: □ | L37: □ | N37: 01_監査対応/[会社名]/05_自主点検成果物/09_工事案件の収益認識会計基準あてはめ | O37: input/01_監査対応_自主点検成果物_ファイルリスト_filtered.xlsx（構成単位・2026年3月期）
A38: 32 | B38: 9 | C38: 長期請負工事案件の洗い出し | D38: データソース・抽出条件 | E38: PKG進行基準売上との一致 | F38: ③共通添付 | G38: 必須 | I38: ○ | J38: ○ | K38: □ | L38: □ | N38: 01_監査対応/[会社名]/05_自主点検成果物/09_工事案件の収益認識会計基準あてはめ | O38: input/01_監査対応_自主点検成果物_ファイルリスト_filtered.xlsx（構成単位・2026年3月期）
A39: 33 | B39: 9 | C39: 長期請負工事案件の洗い出し | D39: 契約書 | E39: 請負高5億円超の案件 | F39: ②根拠資料 | G39: 条件付き | H39: 請負高が閾値超の案件(No.7で提出済を確認) | I39: ○ | J39: ○ | K39: □ | L39: □ | N39: 01_監査対応/[会社名]/05_自主点検成果物/09_工事案件の収益認識会計基準あてはめ | O39: input/01_監査対応_自主点検成果物_ファイルリスト_filtered.xlsx（構成単位・2026年3月期）
A40: 34 | B40: 10 | C40: 実行予算の取得・確認 | D40: 進行基準適用案件毎の実行予算 月次推移 | E40: グラフ・増減コメント | F40: ①成果物本体 | G40: 必須 | I40: ○ | J40: ○ | K40: □ | L40: □ | N40: 01_監査対応/[会社名]/05_自主点検成果物/10_工事案件実効予算分析 | O40: input/01_監査対応_自主点検成果物_ファイルリスト_filtered.xlsx（構成単位・2026年3月期）
A41: 35 | B41: 10 | C41: 実行予算の取得・確認 | D41: データソース・抽出条件 | E41: No.9リストとの整合 | F41: ③共通添付 | G41: 必須 | I41: ○ | J41: ○ | K41: □ | L41: □ | N41: 01_監査対応/[会社名]/05_自主点検成果物/10_工事案件実効予算分析 | O41: input/01_監査対応_自主点検成果物_ファイルリスト_filtered.xlsx（構成単位・2026年3月期）
A42: 36 | B42: 11 | C42: 材料費の実際発生原価の確認 | D42: 原材料購買データと入庫データの月次比較表 | F42: ①成果物本体 | G42: 必須 | I42: ○ | J42: ○ | K42: □ | L42: □ | N42: 01_監査対応/[会社名]/05_自主点検成果物/11_工事案件購買・原材料入出庫分析 | O42: input/01_監査対応_自主点検成果物_ファイルリスト_filtered.xlsx（構成単位・2026年3月期）
...

Sheet チェックポイント確認
A2: 自主点検 チェックポイント確認リスト（構成単位版）
A3: ■ 会社名: ________________________ ■ 実施期: ______________ ■ サイクル (年度末 / 四半期): __________ ■ 記入者: ________________________
A4: 【凡例】 ☑提出 → □ を記入 / 対象外・未実施 → 「該当なし」に □ 記入し、理由を記述のうえ提出可。全行チェックは必須ではありません。
A6: No | B6: 項目No | C6: 点検項目名 | D6: CP_ID | E6: チェックポイント内容 | F6: 年度末 | G6: 四半期 | H6: ☑確認 | I6: 該当なし | J6: 非該当・未確認の理由 | K6: 過去の差し戻し注意 （頻出パターン） | L6: 一次ソース | M6: 備考
A7: 1 | B7: 1 | C7: 売掛金の残高確認 | D7: 01-001 | E7: データソースと抽出条件（手順）の記録が成果物として提出されている | F7: ○ | H7: □ | I7: □ | L7: 統合マスタ v1（内製作成 2026.6）
A8: 2 | B8: 1 | C8: 売掛金の残高確認 | D8: 01-002 | E8: 網羅性が確認できる情報が記載又は提出されている（売掛金残高明細と試算表BSの一致が確認できる） | F8: ○ | H8: □ | I8: □ | L8: 統合マスタ v1（内製作成 2026.6）
A9: 3 | B9: 1 | C9: 売掛金の残高確認 | D9: 01-003 | E9: 残高確認状の発送先一覧と回収結果が提出されている（確認状未発送先・未回収先の区分が明確になっている） | F9: ○ | H9: □ | I9: □ | L9: 統合マスタ v1（内製作成 2026.6）
A10: 4 | B10: 1 | C10: 売掛金の残高確認 | D10: 01-004 | E10: 確認状を回収できなかった相手先について代替手続（入金消込チェックリスト・追加サンプリング等）の実施結果が提出されている | F10: ○ | H10: □ | I10: □ | L10: 統合マスタ v1（内製作成 2026.6）
A11: 5 | B11: 1 | C11: 売掛金の残高確認 | D11: 01-005 | E11: 担当者の確認結果に対し上席者（部門責任者等）のレビュー証跡がある | F11: ○ | H11: □ | I11: □ | L11: 統合マスタ v1（内製作成 2026.6）
A12: 6 | B12: 1 | C12: 売掛金の残高確認 | D12: 01-006 | E12: 差異調整の内容が合理的であり、未入金残高の回収見込みが具体的に説明されている | F12: ○ | H12: □ | I12: □ | L12: 統合マスタ v1（内製作成 2026.6）
A13: 7 | B13: 1 | C13: 売掛金の残高確認 | D13: 01-007 | E13: 代替手続に使用した証憑（注文書・請求書・入金確認等）が適切な外部証憑である（内部帳票のみでの確認は不可） | F13: ○ | H13: □ | I13: □ | L13: 統合マスタ v1（内製作成 2026.6）
A14: 8 | B14: 2 | C14: 在庫の実地棚卸 | D14: 02-001 | E14: データソースと抽出条件（手順）の記録が成果物として提出されている | F14: ○ | H14: □ | I14: □ | L14: 統合マスタ v1（内製作成 2026.6）
A15: 9 | B15: 2 | C15: 在庫の実地棚卸 | D15: 02-002 | E15: 網羅性が確認できる情報が記載又は提出されている（棚卸残高と試算表の一致が確認できる） | F15: ○ | H15: □ | I15: □ | L15: 統合マスタ v1（内製作成 2026.6）
A16: 10 | B16: 2 | C16: 在庫の実地棚卸 | D16: 02-003 | E16: 棚卸実施記録（実施日・実施者・対象品目・数量・差異）が提出されている | F16: ○ | H16: □ | I16: □ | L16: 統合マスタ v1（内製作成 2026.6）
A17: 11 | B17: 2 | C17: 在庫の実地棚卸 | D17: 02-004 | E17: 棚卸差異（帳簿残高との差異）の調整内容と理由が記録されている | F17: ○ | H17: □ | I17: □ | L17: 統合マスタ v1（内製作成 2026.6）
A18: 12 | B18: 2 | C18: 在庫の実地棚卸 | D18: 02-005 | E18: 在庫評価損の計上要否を検討した記録がある（低価法適用対象の確認含む） | F18: ○ | H18: □ | I18: □ | L18: 統合マスタ v1（内製作成 2026.6）
... A27: 21 | B27: 3 | C27: 固定資産の実査 | D27: 03-008 | E27: 第2線立会対象拠点（有形固定資産期末残高1億円以上の拠点）では管理部門担当者の立会証跡が残っている | F27: ○ | H27: □ | I27: □ | L27: 統合マスタ v1（内製作成 2026.6）
A28: 22 | B28: 4 | C28: 滞留債権の分析 | D28: 04-001 | E28: データソースと抽出条件（手順）の記録が成果物として提出されている | F28: ○ | G28: ○ | H28: □ | I28: □ | K28: 計199件指摘 ▶網羅性・試算表不一致(100件): 例)「・網羅性が確認できる資料（試算表との一致確認）の送付をお願いします…」 ▶根拠資料不足(45件): 例)「・自己点検説明資料に記載の金額と試算表の一致がわかる資料の送付をお願いします…」 【構成単位固有】計90件 ▶網羅性・試算表不一致(64件): 例)「・データソース及び抽出条件が分かる資料（画面コピーなど）の送付をお願いします ・網羅性が確認できる資料（試算表との一致確…」 ▶その他(14件): 例)「・データソース及び抽出条件が分かる資料（画面コピーなど）の送付をお願いします」 ▶根拠資料不足(8件): 例)「・No255（カインズホームFC大曲店）の取引発生日が2024/10/29のため、売上計上の妥当性について、補足説明と根…」 ▶コメント・説明不足(4件): 例)「成果物である「04_滞留債権_(札幌デンタル).xlsx」に記載された2先の抽出過程が分かる資料をご提示頂けますでしょう…」 | L28: レビュー指針 No.4（input/自主点検_レビュー指針.xlsx）
A29: 23 | B29: 4 | C29: 滞留債権の分析 | D29: 04-002 | E29: 網羅性が確認できる情報が記載又は提出されている（試算表との一致が確認できる） | F29: ○ | G29: ○ | H29: □ | I29: □ | K29: 計199件指摘 ▶網羅性・試算表不一致(100件): 例)「・網羅性が確認できる資料（試算表との一致確認）の送付をお願いします…」 ▶根拠資料不足(45件): 例)「・自己点検説明資料に記載の金額と試算表の一致がわかる資料の送付をお願いします…」 | L29: レビュー指針 No.4（input/自主点検_レビュー指針.xlsx）
A30: 24 | B30: 4 | C30: 滞留債権の分析 | D30: 04-003 | E30: 回収が遅延している債権全てにつき、回収遅延理由が記載されている | F30: ○ | G30: ○ | H30: □ | I30: □ | K30: 計199件指摘 ▶網羅性・試算表不一致(100件): 例)「・網羅性が確認できる資料（試算表との一致確認）の送付をお願いします…」 ▶根拠資料不足(45件): 例)「・自己点検説明資料に記載の金額と試算表の一致がわかる資料の送付をお願いします…」 | L30: レビュー指針 No.4（input/自主点検_レビュー指針.xlsx）
A31: 25 | B31: 4 | C31: 滞留債権の分析 | D31: 04-004 | E31: 回収遅延理由について、部門責任者等の適切な承認者の承認を得ている | F31: ○ | G31: ○ | H31: □ | I31: □ | K31: 計199件指摘 ▶網羅性・試算表不一致(100件): 例)「・網羅性が確認できる資料（試算表との一致確認）の送付をお願いします…」 ▶根拠資料不足(45件): 例)「・自己点検説明資料に記載の金額と試算表の一致がわかる資料の送付をお願いします…」 | L31: レビュー指針 No.4（input/自主点検_レビュー指針.xlsx）
A32: 26 | B32: 4 | C32: 滞留債権の分析 | D32: 04-005 | E32: 回収遅延理由が合理的である | F32: ○ | G32: ○ | H32: □ | I32: □ | K32: 計199件指摘 ▶網羅性・試算表不一致(100件): 例)「・網羅性が確認できる資料（試算表との一致確認）の送付をお願いします…」 ▶根拠資料不足(45件): 例)「・自己点検説明資料に記載の金額と試算表の一致がわかる資料の送付をお願いします…」 | L32: レビュー指針 No.4（input/自主点検_レビュー指針.xlsx）
A33: 27 | B33: 4 | C33: 滞留債権の分析 | D33: 04-006 | E33: 回収遅延理由が合理的でない場合、売上計上の妥当性に関するコメントが記載されている | F33: ○ | G33: ○ | H33: □ | I33: □ | K33: 計199件指摘 ▶網羅性・試算表不一致(100件): 例)「・網羅性が確認できる資料（試算表との一致確認）の送付をお願いします…」 ▶根拠資料不足(45件): 例)「・自己点検説明資料に記載の金額と試算表の一致がわかる資料の送付をお願いします…」 | L33: レビュー指針 No.4（input/自主点検_レビュー指針.xlsx）
A34: 28 | B34: 4 | C34: 滞留債権の分析 | D34: 04-007 | E34: 注文書などの外部証憑を確認したうえで、適切に売上計上の妥当性をコメントできている | F34: ○ | G34: ○ | H34: □ | I34: □ | K34: 計199件指摘 ▶網羅性・試算表不一致(100件): 例)「・網羅性が確認できる資料（試算表との一致確認）の送付をお願いします…」 ▶根拠資料不足(45件): 例)「・自己点検説明資料に記載の金額と試算表の一致がわかる資料の送付をお願いします…」 | L34: レビュー指針 No.4（input/自主点検_レビュー指針.xlsx）
A35: 29 | B35: 5 | C35: 異常取引の分析 | D35: 05-001 | E35: データソースと抽出条件（手順）の記録が成果物として提出されている | F35: ○ | G35: ○ | H35: □ | I35: □ | K35: 計350件指摘 ▶網羅性・試算表不一致(182件): 例)「・網羅性及び売上伝票/明細と試算表の整合性を確認するため、25年4月~26年3月の全ての売上明細（マイナス含む）の提出をお願い出来ますでしょうか ・マイナスの売…」 ▶根拠資料不足(97件): 例)「下記、売上マイナス仕訳の根拠証憑のご提示をお願いいたします。 ・計上日：20260331 仕訳検索テキスト：022502903161 売上額：△26,759,0…」 【構成単位固有】計123件 ▶網羅性・試算表不一致(100件): 例)「・データソース及び抽出条件が分かる資料（抽出する際の条件を記載した画面スクショなど）の提出をお願い出来ますでしょうか。 …」 ▶コメント・説明不足(12件): 例)「・データソース及び抽出条件が分かる資料（抽出する際の条件を記載した画面スクショなど）の提出をお願い出来ますでしょうか。 …」 ▶根拠資料不足(7件): 例)「証跡フォルダにてご提示いただいております”コンポーネンツ機器部関係 証跡 260427小澤_1”Excelに関しまして、…」 ▶その他(4件): 例)「2025年4月～2026年3月までは確認済みであり、問題ありませんでした。 お聞きになっておられるかと思いますが、202…」 | L35: レビュー指針 No.5（input/自主点検_レビュー指針.xlsx）
A36: 30 | B36: 5 | C36: 異常取引の分析 | D36: 05-002 | E36: 25年4月~26年3月の全ての売上明細（マイナス含む）が提出されている（試算表との一致が確認できる） | F36: ○ | G36: ○ | H36: □ | I36: □ | K36: 計350件指摘 ▶網羅性・試算表不一致(182件): 例)「・網羅性及び売上伝票/明細と試算表の整合性を確認するため、25年4月~26年3月の全ての売上明細（マイナス含む）の提出をお願い出来ますでしょうか ・マイナスの売…」 ▶根拠資料不足(97件): 例)「下記、売上マイナス仕訳の根拠証憑のご提示をお願いいたします。 ・計上日：20260331 仕訳検索テキスト：022502903161 売上額：△26,759,0…」 | L36: レビュー指針 No.5（input/自主点検_レビュー指針.xlsx）
A37: 31 | B37: 5 | C37: 異常取引の分析 | D37: 05-003 | E37: マイナスの売上がある場合、売上計上の妥当性（収益認識基準を満たしているか）を検討したコメントが残されている | F37: ○ | G37: ○ | H37: □ | I37: □ | K37: 計350件指摘 ▶網羅性・試算表不一致(182件): 例)「・網羅性及び売上伝票/明細と試算表の整合性を確認するため、25年4月~26年3月の全ての売上明細（マイナス含む）の提出をお願い出来ますでしょうか ・マイナスの売…」 ▶根拠資料不足(97件): 例)「下記、売上マイナス仕訳の根拠証憑のご提示をお願いいたします。 ・計上日：20260331 仕訳検索テキスト：022502903161 売上額：△26,759,0…」 | L37: レビュー指針 No.5（input/自主点検_レビュー指針.xlsx）
A38: 32 | B38: 5 | C38: 異常取引の分析 | D38: 05-004 | E38: マイナス売上の売上は収益認識基準を満たした売上計上である（例えば、リスクの高いマイナス取引については、根拠資料を確認したうえで①売上計上と②取消それぞれの観点で合理的なコメントが出来ているかの確認が必要） | F38: ○ | G38: ○ | H38: □ | I38: □ | K38: 計350件指摘 ▶網羅性・試算表不一致(182件): 例)「・網羅性及び売上伝票/明細と試算表の整合性を確認するため、25年4月~26年3月の全ての売上明細（マイナス含む）の提出をお願い出来ますでしょうか ・マイナスの売…」 ▶根拠資料不足(97件): 例)「下記、売上マイナス仕訳の根拠証憑のご提示をお願いいたします。 ・計上日：20260331 仕訳検索テキスト：022502903161 売上額：△26,759,0…」 | L38: レビュー指針 No.5（input/自主点検_レビュー指針.xlsx） | M38: 【構成単位】2次レビュー対象閾値：金額2,000万円以上・最低5件（非構成単位は3件）
A39: 33 | B39: 5 | C39: 異常取引の分析 | D39: 05-005 | E39: 収益認識基準を満たさない売上計上の場合は、会計処理の顛末が記載されている | F39: ○ | G39: ○ | H39: □ | I39: □ | K39: 計350件指摘 ▶網羅性・試算表不一致(182件): 例)「・網羅性及び売上伝票/明細と試算表の整合性を確認するため、25年4月~26年3月の全ての売上明細（マイナス含む）の提出をお願い出来ますでしょうか ・マイナスの売…」 ▶根拠資料不足(97件): 例)「下記、売上マイナス仕訳の根拠証憑のご提示をお願いいたします。 ・計上日：20260331 仕訳検索テキスト：022502903161 売上額：△26,759,0…」 | L39: レビュー指針 No.5（input/自主点検_レビュー指針.xlsx） | M39: 【構成単位】2次レビュー対象閾値：金額2,000万円以上・最低5件（非構成単位は3件）
A40: 34 | B40: 6 | C40: 売上の期末変動分析 | D40: 06-001 | E40: データソースと抽出条件（手順）の記録が成果物として提出されている | F40: ○ | G40: ○ | H40: □ | I40: □ | K40: 計199件指摘 ▶網羅性・試算表不一致(95件): 例)「・データソース及び抽出条件が分かる資料（画面コピーなど）の送付をお願いします ・網羅性が確認できる資料（試算表との一致確認）の送付をお願いします…」 ▶根拠資料不足(51件): 例)「・データソース及び抽出条件が分かる資料（画面コピーなど）の提出してください ・網羅性が確認できる資料（試算表との一致確認）の提出してください ・特に四半期末月に…」 【構成単位固有】計88件 ▶網羅性・試算表不一致(71件): 例)「・データソース及び抽出条件が分かる資料（画面コピーなど）の送付をお願いします ・網羅性が確認できる資料（試算表との一致確…」 ▶コメント・説明不足(9件): 例)「増減のコメントに関し、前月比で+-20%の増減がある場合のコメントが不足しているように見受けられましたので、ご確認をお願…」 ▶その他(7件): 例)「・Please send us documentation that shows the data sources an…」 ▶根拠資料不足(1件): 例)「・データソース及び抽出条件が分かる資料（画面コピーなど）の送付をお願いします ・前年度同月比較だけでなく、前月比の増減検…」 | L40: レビュー指針 No.6（input/自主点検_レビュー指針.xlsx）
A41: 35 | B41: 6 | C41: 売上の期末変動分析 | D41: 06-002 | E41: 網羅性が確認できる情報が記載又は提出されている（試算表との一致が確認できる） | F41: ○ | G41: ○ | H41: □ | I41: □ | K41: 計199件指摘 ▶網羅性・試算表不一致(95件): 例)「・データソース及び抽出条件が分かる資料（画面コピーなど）の送付をお願いします ・網羅性が確認できる資料（試算表との一致確認）の送付をお願いします…」 ▶根拠資料不足(51件): 例)「・データソース及び抽出条件が分かる資料（画面コピーなど）の提出してください ・網羅性が確認できる資料（試算表との一致確認）の提出してください ・特に四半期末月に…」 | L41: レビュー指針 No.6（input/自主点検_レビュー指針.xlsx）
A42: 36 | B42: 6 | C42: 売上の期末変動分析 | D42: 06-003 | E42: 前年同期・前月比較ともに、10百万円の変動、かつ、20%以上の変動がある場合、増減コメントがされている | F42: ○ | G42: ○ | H42: □ | I42: □ | K42: 計199件指摘 ▶網羅性・試算表不一致(95件): 例)「・データソース及び抽出条件が分かる資料（画面コピーなど）の送付をお願いします ・網羅性が確認できる資料（試算表との一致確認）の送付をお願いします…」 ▶根拠資料不足(51件): 例)「・データソース及び抽出条件が分かる資料（画面コピーなど）の提出してください ・網羅性が確認できる資料（試算表との一致確認）の提出してください ・特に四半期末月に…」 | L42: レビュー指針 No.6（input/自主点検_レビュー指針.xlsx）
A43: 37 | B43: 6 | C43: 売上の期末変動分析 | D43: 06-004 | E43: 増減分析コメントにて、要因毎の影響金額を記載している（最低限、6割～7割程度） | F43: ○ | G43: ○ | H43: □ | I43: □ | K43: 計199件指摘 ▶網羅性・試算表不一致(95件): 例)「・データソース及び抽出条件が分かる資料（画面コピーなど）の送付をお願いします ・網羅性が確認できる資料（試算表との一致確認）の送付をお願いします…」 ▶根拠資料不足(51件): 例)「・データソース及び抽出条件が分かる資料（画面コピーなど）の提出してください ・網羅性が確認できる資料（試算表との一致確認）の提出してください ・特に四半期末月に…」 ▶【構成単位固有要件】要因毎の影響金額記載（6〜7割以上）は構成単位の1次レビュー要件（非構成単位は定量記載不要） | L43: レビュー指針 No.6（input/自主点検_レビュー指針.xlsx）
A44: 38 | B44: 6 | C44: 売上の期末変動分析 | D44: 06-005 | E44: 特に四半期末月に上昇傾向があった場合に、根拠資料に基づいて売上計上の妥当性を検証している。また、検証した旨がコメントされている。 | F44: ○ | G44: ○ | H44: □ | I44: □ | K44: 計199件指摘 ▶網羅性・試算表不一致(95件): 例)「・データソース及び抽出条件が分かる資料（画面コピーなど）の送付をお願いします ・網羅性が確認できる資料（試算表との一致確認）の送付をお願いします…」 ▶根拠資料不足(51件): 例)「・データソース及び抽出条件が分かる資料（画面コピーなど）の提出してください ・網羅性が確認できる資料（試算表との一致確認）の提出してください ・特に四半期末月に…」 | L44: レビュー指針 No.6（input/自主点検_レビュー指針.xlsx）
A45: 39 | B45: 6 | C45: 売上の期末変動分析 | D45: 06-006 | E45: 増減分析コメントにて、増減内容の説明になっている | F45: ○ | G45: ○ | H45: □ | I45: □ | K45: 計199件指摘 ▶網羅性・試算表不一致(95件): 例)「・データソース及び抽出条件が分かる資料（画面コピーなど）の送付をお願いします ・網羅性が確認できる資料（試算表との一致確認）の送付をお願いします…」 ▶根拠資料不足(51件): 例)「・データソース及び抽出条件が分かる資料（画面コピーなど）の提出してください ・網羅性が確認できる資料（試算表との一致確認）の提出してください ・特に四半期末月に…」 | L45: レビュー指針 No.6（input/自主点検_レビュー指針.xlsx）
A46: 40 | B46: 6 | C46: 売上の期末変動分析 | D46: 06-007 | E46: 増減分析コメントにて、金額推移と整合した説明になっている | F46: ○ | G46: ○ | H46: □ | I46: □ | K46: 計199件指摘 ▶網羅性・試算表不一致(95件): 例)「・データソース及び抽出条件が分かる資料（画面コピーなど）の送付をお願いします ・網羅性が確認できる資料（試算表との一致確認）の送付をお願いします…」 ▶根拠資料不足(51件): 例)「・データソース及び抽出条件が分かる資料（画面コピーなど）の提出してください ・網羅性が確認できる資料（試算表との一致確認）の提出してください ・特に四半期末月に…」 | L46: レビュー指針 No.6（input/自主点検_レビュー指針.xlsx）
A47: 41 | B47: 6 | C47: 売上の期末変動分析 | D47: 06-008 | E47: 前年同期・前月比較ともに、10百万円の変動、かつ、20%以上の変動がある場合、増減コメントがされている 特に四半期末月に上昇傾向があった場合に、増減分析コメントにて、要因を記載している | F47: ○ | G47: ○ | H47: □ | I47: □ | K47: 計199件指摘 ▶網羅性・試算表不一致(95件): 例)「・データソース及び抽出条件が分かる資料（画面コピーなど）の送付をお願いします ・網羅性が確認できる資料（試算表との一致確認）の送付をお願いします…」 ▶根拠資料不足(51件): 例)「・データソース及び抽出条件が分かる資料（画面コピーなど）の提出してください ・網羅性が確認できる資料（試算表との一致確認）の提出してください ・特に四半期末月に…」 | L47: レビュー指針 No.6（input/自主点検_レビュー指針.xlsx） | M47: 【非構成単位専用】構成単位版では06-003〜06-005が適用（定量要件・四半期末月妥当性検証あり）。
A48: 42 | B48: 7 | C48: 収益認識アンケート（証憑提出含む） | D48: 07-001 | E48: データソースと抽出条件（手順）の記録が成果物として提出されている | F48: ○ | G48: ○ | H48: □ | I48: □ | L48: 統合マスタ v1（内製作成 2026.6）
A49: 43 | B49: 7 | C49: 収益認識アンケート（証憑提出含む） | D49: 07-002 | E49: 網羅性が確認できる情報が記載又は提出されている（売上明細データと試算表PLの一致が事前確認されている） | F49: ○ | G49: ○ | H49: □ | I49: □ | L49: 統合マスタ v1（内製作成 2026.6）
A50: 44 | B50: 7 | C50: 収益認識アンケート（証憑提出含む） | D50: 07-003 | E50: アンケートの全4セクション（概要整理・商流図・チェックシート・PL金額）が記入・提出されている | F50: ○ | G50: ○ | H50: □ | I50: □ | L50: 統合マスタ v1（内製作成 2026.6）
...

Sheet 点検項目インデックス
A2: 自主点検 点検項目インデックス（28項目）
A3: ■ 会社名: ________________________ ■ 実施期: ______________ ■ サイクル (年度末 / 四半期): __________ ■ 記入者: ________________________
A4: 【凡例】 ☑提出 → □ を記入 / 対象外・未実施 → 「該当なし」に □ 記入し、理由を記述のうえ提出可。全行チェックは必須ではありません。
A6: No | B6: 点検項目名 | C6: 関連科目・取引 | D6: 提出物数 | E6: CP数 | F6: 年度末 対象 | G6: 四半期 対象 | H6: 過去事例 件数 | I6: 備考
A7: 1 | B7: 売掛金の残高確認 | C7: 売掛金、売上 | D7: =COUNTIF(提出物チェックリスト!$B$7:$B$88,$A7) -> 5 | E7: =COUNTIF(チェックポイント確認!$B$7:$B$169,$A7) -> 7 | F7: ○ | H7: 0
A8: 2 | B8: 在庫の実地棚卸 | C8: 棚卸資産、売上 | D8: =COUNTIF(提出物チェックリスト!$B$7:$B$88,$A8) -> 2 | E8: =COUNTIF(チェックポイント確認!$B$7:$B$169,$A8) -> 6 | F8: ○ | H8: 0
A9: 3 | B9: 固定資産の実査 | C9: 固定資産 | D9: =COUNTIF(提出物チェックリスト!$B$7:$B$88,$A9) -> 6 | E9: =COUNTIF(チェックポイント確認!$B$7:$B$169,$A9) -> 8 | F9: ○ | H9: 0
A10: 4 | B10: 滞留債権の分析 | C10: 売掛金 | D10: =COUNTIF(提出物チェックリスト!$B$7:$B$88,$A10) -> 4 | E10: =COUNTIF(チェックポイント確認!$B$7:$B$169,$A10) -> 7 | F10: ○ | G10: ○ | H10: 199
A11: 5 | B11: 異常取引の分析 | C11: 売上 | D11: =COUNTIF(提出物チェックリスト!$B$7:$B$88,$A11) -> 4 | E11: =COUNTIF(チェックポイント確認!$B$7:$B$169,$A11) -> 5 | F11: ○ | G11: ○ | H11: 350
A12: 6 | B12: 売上の期末変動分析 | C12: 売上 | D12: =COUNTIF(提出物チェックリスト!$B$7:$B$88,$A12) -> 3 | E12: =COUNTIF(チェックポイント確認!$B$7:$B$169,$A12) -> 8 | F12: ○ | G12: ○ | H12: 199
A13: 7 | B13: 収益認識アンケート（証憑提出含む） | C13: 売上 | D13: =COUNTIF(提出物チェックリスト!$B$7:$B$88,$A13) -> 3 | E13: =COUNTIF(チェックポイント確認!$B$7:$B$169,$A13) -> 7 | F13: ○ | G13: ○ | H13: 0
A14: 8 | B14: 売上のカットオフテスト | C14: 売上 | D14: =COUNTIF(提出物チェックリスト!$B$7:$B$88,$A14) -> 3 | E14: =COUNTIF(チェックポイント確認!$B$7:$B$169,$A14) -> 8 | F14: ○ | G14: ○ | H14: 285
A15: 9 | B15: 長期請負工事案件の洗い出し | C15: 売上、仕掛品 | D15: =COUNTIF(提出物チェックリスト!$B$7:$B$88,$A15) -> 3 | E15: =COUNTIF(チェックポイント確認!$B$7:$B$169,$A15) -> 6 | F15: ○ | G15: ○ | H15: 22
A16: 10 | B16: 実行予算の取得・確認 | C16: 売上、仕掛品 | D16: =COUNTIF(提出物チェックリスト!$B$7:$B$88,$A16) -> 2 | E16: =COUNTIF(チェックポイント確認!$B$7:$B$169,$A16) -> 5 | F16: ○ | G16: ○ | H16: 19
A17: 11 | B17: 材料費の実際発生原価の確認 | C17: 売上原価、仕掛品 | D17: =COUNTIF(提出物チェックリスト!$B$7:$B$88,$A17) -> 3 | E17: =COUNTIF(チェックポイント確認!$B$7:$B$169,$A17) -> 5 | F17: ○ | G17: ○ | H17: 17
A18: 12 | B18: 進捗率の算定根拠の確認 | C18: 売上、仕掛品 | D18: =COUNTIF(提出物チェックリスト!$B$7:$B$88,$A18) -> 3 | E18: =COUNTIF(チェックポイント確認!$B$7:$B$169,$A18) -> 7 | F18: ○ | G18: ○ | H18: 22
A19: 13 | B19: 経費の実際発生原価の確認 | C19: 売上原価、仕掛品 | D19: =COUNTIF(提出物チェックリスト!$B$7:$B$88,$A19) -> 3 | E19: =COUNTIF(チェックポイント確認!$B$7:$B$169,$A19) -> 4 | F19: ○ | G19: ○ | H19: 14
A20: 14 | B20: 原価振替取引の要因説明 | C20: 売上原価 | D20: =COUNTIF(提出物チェックリスト!$B$7:$B$88,$A20) -> 3 | E20: =COUNTIF(チェックポイント確認!$B$7:$B$169,$A20) -> 5 | F20: ○ | G20: ○ | H20: 20
A21: 15 | B21: 低粗利案件の分析 | C21: 売上原価 | D21: =COUNTIF(提出物チェックリスト!$B$7:$B$88,$A21) -> 3 | E21: =COUNTIF(チェックポイント確認!$B$7:$B$169,$A21) -> 7 | F21: ○ | G21: ○ | H21: 18
... A29: 23 | B29: 固定資産の資産性確認 | C29: 固定資産 | D29: =COUNTIF(提出物チェックリスト!$B$7:$B$88,$A29) -> 3 | E29: =COUNTIF(チェックポイント確認!$B$7:$B$169,$A29) -> 4 | F29: ○ | G29: ○ | H29: 139
A30: 24 | B30: 資産除去債務の計上要否の判断を証憑に基づいて整理（証憑提出含む） | C30: 固定資産、資産除去債務 | D30: =COUNTIF(提出物チェックリスト!$B$7:$B$88,$A30) -> 2 | E30: =COUNTIF(チェックポイント確認!$B$7:$B$169,$A30) -> 5 | F30: ○ | H30: 1
A31: 25 | B31: 減損テスト | C31: 固定資産、のれん、投資その他の資産 | D31: =COUNTIF(提出物チェックリスト!$B$7:$B$88,$A31) -> 4 | E31: =COUNTIF(チェックポイント確認!$B$7:$B$169,$A31) -> 6 | F31: ○ | G31: ○ | H31: 169
A32: 26 | B32: 賞与引当金の計上確認 | C32: 賞与引当金、賞与 | D32: =COUNTIF(提出物チェックリスト!$B$7:$B$88,$A32) -> 4 | E32: =COUNTIF(チェックポイント確認!$B$7:$B$169,$A32) -> 8 | F32: ○ | G32: ○ | H32: 193
A33: 27 | B33: 自主点検チェックリスト | C33: 全般 | D33: =COUNTIF(提出物チェックリスト!$B$7:$B$88,$A33) -> 1 | E33: =COUNTIF(チェックポイント確認!$B$7:$B$169,$A33) -> 7 | F33: ○ | G33: ○ | H33: 1
A34: 28 | B34: 財務分析 | C34: 全般 | D34: =COUNTIF(提出物チェックリスト!$B$7:$B$88,$A34) -> 2 | E34: =COUNTIF(チェックポイント確認!$B$7:$B$169,$A34) -> 7 | F34: ○ | G34: ○ | H34: 9
A35: 合計 | D35: =SUM(D7:D34) -> 82 | E35: =SUM(E7:E34) -> 163 | H35: =SUM(H7:H34) -> 2495
