Workbook

Sheet 自主点検項目
A1: No | B1: 自主点検項目名 | C1: 関連科目・取引 | D1: 備考
A2: 1 | B2: 売掛金の残高確認 | C2: 売掛金、売上
A3: 2 | B3: 在庫の実地棚卸 | C3: 棚卸資産、売上
A4: 3 | B4: 固定資産の実査 | C4: 固定資産
A5: 4 | B5: 滞留債権の分析 | C5: 売掛金
A6: 5 | B6: 異常取引の分析 | C6: 売上
A7: 6 | B7: 売上の期末変動分析 | C7: 売上
A8: 7 | B8: 収益認識アンケート（証憑提出含む） | C8: 売上
A9: 8 | B9: 売上のカットオフテスト | C9: 売上
A10: 9 | B10: 長期請負工事案件の洗い出し | C10: 売上、仕掛品
A11: 10 | B11: 実行予算の取得・確認 | C11: 売上、仕掛品
A12: 11 | B12: 材料費の実際発生原価の確認 | C12: 売上原価、仕掛品
A13: 12 | B13: 進捗率の算定根拠の確認 | C13: 売上、仕掛品
... A29: 28 | B29: 財務分析 | C29: 全般

Sheet 提出物
A1: No | B1: 自主点検項目No | C1: 自主点検項目名 | D1: 提出物名 | E1: 提出物詳細 | F1: 区分 | G1: 提出区分 | H1: 適用の目安（条件付き・代替・排他の場合） | I1: 提出 | J1: 該当なし | K1: 非該当・未提出の理由 | L1: 備考
A2: 1 | B2: 1 | C2: =IFERROR(INDEX(自主点検項目!$B:$B,MATCH(B2,自主点検項目!$A:$A,0)),"") -> 売掛金の残高確認 | D2: 残高確認状の回収結果・差異調整結果 | F2: ①成果物本体 | G2: 必須
A3: 2 | B3: 1 | C3: =IFERROR(INDEX(自主点検項目!$B:$B,MATCH(B3,自主点検項目!$A:$A,0)),"") -> 売掛金の残高確認 | D3: 代替手続実施結果 | E3: 代替手続チェックリスト・入金消込管理表の検証資料 | F3: ①成果物本体 | G3: 条件付き | H3: 確認状を回収できない/発送しない相手先(個人・官公庁等)がある場合
A4: 3 | B4: 1 | C4: =IFERROR(INDEX(自主点検項目!$B:$B,MATCH(B4,自主点検項目!$A:$A,0)),"") -> 売掛金の残高確認 | D4: 追加サンプリング結果 | F4: ②根拠資料 | G4: 条件付き | H4: 2026年6月以降入金予定の3月末売掛金残高が閾値以上
A5: 4 | B5: 1 | C5: =IFERROR(INDEX(自主点検項目!$B:$B,MATCH(B5,自主点検項目!$A:$A,0)),"") -> 売掛金の残高確認 | D5: 売掛金明細 | E5: 2026年3月末 | F5: ③共通添付 | G5: 必須
A6: 5 | B6: 1 | C6: =IFERROR(INDEX(自主点検項目!$B:$B,MATCH(B6,自主点検項目!$A:$A,0)),"") -> 売掛金の残高確認 | D6: 試算表＋連結PKGまでの調整 | E6: 3月末 | F6: ③共通添付 | G6: 必須
A7: 6 | B7: 2 | C7: =IFERROR(INDEX(自主点検項目!$B:$B,MATCH(B7,自主点検項目!$A:$A,0)),"") -> 在庫の実地棚卸 | D7: 実地棚卸の結果 | E7: 別途ガイダンスに従い提出 | F7: ①成果物本体 | G7: 必須
A8: 7 | B8: 2 | C8: =IFERROR(INDEX(自主点検項目!$B:$B,MATCH(B8,自主点検項目!$A:$A,0)),"") -> 在庫の実地棚卸 | D8: 預り売上に関する親会社への情報・検討内容 | F8: ①成果物本体 | G8: 条件付き | H8: 預り売上(請求済未出荷)を計上している場合(原則禁止)
A9: 8 | B9: 3 | C9: =IFERROR(INDEX(自主点検項目!$B:$B,MATCH(B9,自主点検項目!$A:$A,0)),"") -> 固定資産の実査 | D9: 固定資産実査報告書 | E9: 確定版:エクセル＋部署長検印済PDF | F9: ①成果物本体 | G9: 必須
A10: 9 | B10: 3 | C10: =IFERROR(INDEX(自主点検項目!$B:$B,MATCH(B10,自主点検項目!$A:$A,0)),"") -> 固定資産の実査 | D10: 現物照合の写真 | F10: ②根拠資料 | G10: 必須
A11: 10 | B11: 3 | C11: =IFERROR(INDEX(自主点検項目!$B:$B,MATCH(B11,自主点検項目!$A:$A,0)),"") -> 固定資産の実査 | D11: 代替証跡 | E11: 登記簿・リース契約書・使用実績資料等 | F11: ②根拠資料 | G11: 代替 | H11: 現物カウントが困難な資産がある場合
A12: 11 | B12: 3 | C12: =IFERROR(INDEX(自主点検項目!$B:$B,MATCH(B12,自主点検項目!$A:$A,0)),"") -> 固定資産の実査 | D12: 固定資産訂正仕訳が必要な資産の報告書 | F12: ①成果物本体 | G12: 条件付き | H12: 現物照合で訂正(除却漏れ・資産性等)が発覚した場合
A13: 12 | B13: 3 | C13: =IFERROR(INDEX(自主点検項目!$B:$B,MATCH(B13,自主点検項目!$A:$A,0)),"") -> 固定資産の実査 | D13: 修正仕訳のエビデンス | E13: Proplusモニターシート・Biz∫仕訳 | F13: ②根拠資料 | G13: 条件付き | H13: 修正仕訳を起票した場合
A14: 13 | B14: 3 | C14: =IFERROR(INDEX(自主点検項目!$B:$B,MATCH(B14,自主点検項目!$A:$A,0)),"") -> 固定資産の実査 | D14: 独立立会人による実査立会結果 | F14: ①成果物本体 | G14: 条件付き | H14: 第2線立会対象(規模条件)
A15: 14 | B15: 4 | C15: =IFERROR(INDEX(自主点検項目!$B:$B,MATCH(B15,自主点検項目!$A:$A,0)),"") -> 滞留債権の分析 | D15: 期末滞留債権一覧 | E15: 回収遅延理由・最新回収予定日 | F15: ①成果物本体 | G15: 必須
A16: 15 | B16: 4 | C16: =IFERROR(INDEX(自主点検項目!$B:$B,MATCH(B16,自主点検項目!$A:$A,0)),"") -> 滞留債権の分析 | D16: 売掛金明細・試算表の一致 | E16: データソース・抽出条件 | F16: ③共通添付 | G16: 必須
A17: 16 | B17: 4 | C17: =IFERROR(INDEX(自主点検項目!$B:$B,MATCH(B17,自主点検項目!$A:$A,0)),"") -> 滞留債権の分析 | D17: 回収遅延理由の承認証跡 | F17: ②根拠資料 | G17: 代替 | H17: 部門責任者等の承認(チェックリスト承認で代替可)
A18: 17 | B18: 4 | C18: =IFERROR(INDEX(自主点検項目!$B:$B,MATCH(B18,自主点検項目!$A:$A,0)),"") -> 滞留債権の分析 | D18: 外部証憑 | E18: 契約書・注文書・納品書 等 | F18: ②根拠資料 | G18: 条件付き | H18: 回収遅延理由が合理的でない債権がある場合
A19: 18 | B19: 5 | C19: =IFERROR(INDEX(自主点検項目!$B:$B,MATCH(B19,自主点検項目!$A:$A,0)),"") -> 異常取引の分析 | D19: 年間取引データ | E19: 取引先別・案件別ソート,マイナス理由記載 | F19: ①成果物本体 | G19: 必須
A20: 19 | B20: 5 | C20: =IFERROR(INDEX(自主点検項目!$B:$B,MATCH(B20,自主点検項目!$A:$A,0)),"") -> 異常取引の分析 | D20: 翌期4月分の二次提出データ | F20: ①成果物本体 | G20: 必須
A21: 20 | B21: 5 | C21: =IFERROR(INDEX(自主点検項目!$B:$B,MATCH(B21,自主点検項目!$A:$A,0)),"") -> 異常取引の分析 | D21: データソース・抽出条件 | E21: 全明細と試算表の一致 | F21: ③共通添付 | G21: 必須
A22: 21 | B22: 5 | C22: =IFERROR(INDEX(自主点検項目!$B:$B,MATCH(B22,自主点検項目!$A:$A,0)),"") -> 異常取引の分析 | D22: マイナス取引の根拠資料 | E22: ①計上妥当②取消妥当 | F22: ②根拠資料 | G22: 条件付き | H22: 2次レビューで確認が必要な取引
A23: 22 | B23: 6 | C23: =IFERROR(INDEX(自主点検項目!$B:$B,MATCH(B23,自主点検項目!$A:$A,0)),"") -> 売上の期末変動分析 | D23: 月次の売上・粗利推移データ | E23: グラフ・増減分析コメント | F23: ①成果物本体 | G23: 必須
A24: 23 | B24: 6 | C24: =IFERROR(INDEX(自主点検項目!$B:$B,MATCH(B24,自主点検項目!$A:$A,0)),"") -> 売上の期末変動分析 | D24: データソース・抽出条件 | E24: 試算表との一致 | F24: ③共通添付 | G24: 必須
A25: 24 | B25: 6 | C25: =IFERROR(INDEX(自主点検項目!$B:$B,MATCH(B25,自主点検項目!$A:$A,0)),"") -> 売上の期末変動分析 | D25: 増減要因の根拠証憑 | F25: ②根拠資料 | G25: 条件付き | H25: 四半期末月に上昇傾向・重要変動がある場合
A26: 25 | B26: 7 | C26: =IFERROR(INDEX(自主点検項目!$B:$B,MATCH(B26,自主点検項目!$A:$A,0)),"") -> 収益認識アンケート（証憑提出含む） | D26: 収益認識アンケート回答 | E26: SPファイル直接更新/メール返信 | F26: ①成果物本体 | G26: 必須
A27: 26 | B27: 7 | C27: =IFERROR(INDEX(自主点検項目!$B:$B,MATCH(B27,自主点検項目!$A:$A,0)),"") -> 収益認識アンケート（証憑提出含む） | D27: 契約書PDF | E27: 取引基本契約書等 | F27: ②根拠資料 | G27: 条件付き | H27: 年間売上金額が閾値以上の取引(半期提出済は再提出不要)
A28: 27 | B28: 7 | C28: =IFERROR(INDEX(自主点検項目!$B:$B,MATCH(B28,自主点検項目!$A:$A,0)),"") -> 収益認識アンケート（証憑提出含む） | D28: 当期の売上明細データ | E28: 試算表との一致を事前確認 | F28: ③共通添付 | G28: 必須
A29: 28 | B29: 8 | C29: =IFERROR(INDEX(自主点検項目!$B:$B,MATCH(B29,自主点検項目!$A:$A,0)),"") -> 売上のカットオフテスト | D29: 売上明細データ | E29: 検証結果コメント付 | F29: ①成果物本体 | G29: 必須
A30: 29 | B30: 8 | C30: =IFERROR(INDEX(自主点検項目!$B:$B,MATCH(B30,自主点検項目!$A:$A,0)),"") -> 売上のカットオフテスト | D30: データソース・抽出条件 | E30: 3月単月の試算表一致 | F30: ③共通添付 | G30: 必須
A31: 30 | B31: 8 | C31: =IFERROR(INDEX(自主点検項目!$B:$B,MATCH(B31,自主点検項目!$A:$A,0)),"") -> 売上のカットオフテスト | D31: 収益認識の根拠資料 | F31: ②根拠資料 | G31: 条件付き | H31: 一定金額以上の取引に限る
A32: 31 | B32: 9 | C32: =IFERROR(INDEX(自主点検項目!$B:$B,MATCH(B32,自主点検項目!$A:$A,0)),"") -> 長期請負工事案件の洗い出し | D32: 進行基準適用案件リスト | E32: 履行義務毎の判断根拠 | F32: ①成果物本体 | G32: 必須
A33: 32 | B33: 9 | C33: =IFERROR(INDEX(自主点検項目!$B:$B,MATCH(B33,自主点検項目!$A:$A,0)),"") -> 長期請負工事案件の洗い出し | D33: データソース・抽出条件 | E33: PKG進行基準売上との一致 | F33: ③共通添付 | G33: 必須
A34: 33 | B34: 9 | C34: =IFERROR(INDEX(自主点検項目!$B:$B,MATCH(B34,自主点検項目!$A:$A,0)),"") -> 長期請負工事案件の洗い出し | D34: 契約書 | E34: 請負高5億円超の案件 | F34: ②根拠資料 | G34: 条件付き | H34: 請負高が閾値超の案件(No.7で提出済を確認)
A35: 34 | B35: 10 | C35: =IFERROR(INDEX(自主点検項目!$B:$B,MATCH(B35,自主点検項目!$A:$A,0)),"") -> 実行予算の取得・確認 | D35: 進行基準適用案件毎の実行予算 月次推移 | E35: グラフ・増減コメント | F35: ①成果物本体 | G35: 必須
A36: 35 | B36: 10 | C36: =IFERROR(INDEX(自主点検項目!$B:$B,MATCH(B36,自主点検項目!$A:$A,0)),"") -> 実行予算の取得・確認 | D36: データソース・抽出条件 | E36: No.9リストとの整合 | F36: ③共通添付 | G36: 必須
A37: 36 | B37: 11 | C37: =IFERROR(INDEX(自主点検項目!$B:$B,MATCH(B37,自主点検項目!$A:$A,0)),"") -> 材料費の実際発生原価の確認 | D37: 原材料購買データと入庫データの月次比較表 | F37: ①成果物本体 | G37: 必須
A38: 37 | B38: 11 | C38: =IFERROR(INDEX(自主点検項目!$B:$B,MATCH(B38,自主点検項目!$A:$A,0)),"") -> 材料費の実際発生原価の確認 | D38: 工事案件原価明細と出庫データの紐づけ | E38: 案件毎シート | F38: ①成果物本体 | G38: 必須
A39: 38 | B39: 11 | C39: =IFERROR(INDEX(自主点検項目!$B:$B,MATCH(B39,自主点検項目!$A:$A,0)),"") -> 材料費の実際発生原価の確認 | D39: 差異取引の外部根拠証憑 | F39: ②根拠資料 | G39: 条件付き | H39: 入出庫と整合しない購買・原価明細がある場合
A40: 39 | B40: 12 | C40: =IFERROR(INDEX(自主点検項目!$B:$B,MATCH(B40,自主点検項目!$A:$A,0)),"") -> 進捗率の算定根拠の確認 | D40: 進行基準適用案件毎の進捗率 月次推移表 | E40: 要因コメント | F40: ①成果物本体 | G40: 必須
...

Sheet レビュー指針
A1: レビュー項目No | B1: 自主点検項目No | C1: 自主点検項目名 | D1: カテゴリ | E1: レビュー区分 | F1: 構成単位区分 | G1: 種別 | H1: レビュー項目 | I1: メモ | J1: 紐づくCP数 | K1: 紐づく事例件数
A2: 1 | B2: 4 | C2: =IFERROR(INDEX(自主点検項目!$B:$B,MATCH(B2,自主点検項目!$A:$A,0)),"") -> 滞留債権の分析 | D2: 成果物 | E2: 1次レビュー | F2: 共通 | G2: レビュー項目 | H2: データソースと抽出条件（手順）の記録が成果物として提出されている | I2: 試算表との一致確認がなく、データソース・抽出手順も不明の資料は不備ありとする | J2: =COUNTIF(チェックポイント!$I:$I,A2) -> 2 | K2: =SUMIF(チェックポイント!$I:$I,A2,チェックポイント!$G:$G) -> 71
A3: 2 | B3: 4 | C3: =IFERROR(INDEX(自主点検項目!$B:$B,MATCH(B3,自主点検項目!$A:$A,0)),"") -> 滞留債権の分析 | D3: 成果物 | E3: 1次レビュー | F3: 共通 | G3: レビュー項目 | H3: 網羅性が確認できる情報が記載又は提出されている（試算表との一致が確認できる） | I3: 網羅性の確認 | J3: =COUNTIF(チェックポイント!$I:$I,A3) -> 1 | K3: =SUMIF(チェックポイント!$I:$I,A3,チェックポイント!$G:$G) -> 85
A4: 3 | B4: 4 | C4: =IFERROR(INDEX(自主点検項目!$B:$B,MATCH(B4,自主点検項目!$A:$A,0)),"") -> 滞留債権の分析 | D4: 成果物 | E4: 1次レビュー | F4: 共通 | G4: レビュー項目 | H4: 回収が遅延している債権全てにつき、回収遅延理由が記載されている | J4: =COUNTIF(チェックポイント!$I:$I,A4) -> 2 | K4: =SUMIF(チェックポイント!$I:$I,A4,チェックポイント!$G:$G) -> 15
A5: 4 | B5: 4 | C5: =IFERROR(INDEX(自主点検項目!$B:$B,MATCH(B5,自主点検項目!$A:$A,0)),"") -> 滞留債権の分析 | D5: 成果物 | E5: 1次レビュー | F5: 共通 | G5: レビュー項目 | H5: 回収遅延理由について、部門責任者等の適切な承認者の承認を得ている | I5: 承認証跡がなくても追加依頼は不要（チェックリストの承認を承認証跡として考えればok） | J5: =COUNTIF(チェックポイント!$I:$I,A5) -> 2 | K5: =SUMIF(チェックポイント!$I:$I,A5,チェックポイント!$G:$G) -> 3
A6: 5 | B6: 4 | C6: =IFERROR(INDEX(自主点検項目!$B:$B,MATCH(B6,自主点検項目!$A:$A,0)),"") -> 滞留債権の分析 | D6: コメントの妥当性 | E6: 2次レビュー | F6: 共通 | G6: レビュー項目 | H6: 回収遅延理由が合理的である | J6: =COUNTIF(チェックポイント!$I:$I,A6) -> 0 | K6: =SUMIF(チェックポイント!$I:$I,A6,チェックポイント!$G:$G) -> 0
A7: 6 | B7: 4 | C7: =IFERROR(INDEX(自主点検項目!$B:$B,MATCH(B7,自主点検項目!$A:$A,0)),"") -> 滞留債権の分析 | D7: 対応の十分性 | E7: 2次レビュー | F7: 共通 | G7: レビュー項目 | H7: 回収遅延理由が合理的でない場合、売上計上の妥当性に関するコメントが記載されている | J7: =COUNTIF(チェックポイント!$I:$I,A7) -> 0 | K7: =SUMIF(チェックポイント!$I:$I,A7,チェックポイント!$G:$G) -> 0
A8: 7 | B8: 4 | C8: =IFERROR(INDEX(自主点検項目!$B:$B,MATCH(B8,自主点検項目!$A:$A,0)),"") -> 滞留債権の分析 | D8: コメントの妥当性 | E8: 2次レビュー | F8: 共通 | G8: レビュー項目 | H8: 注文書などの外部証憑を確認したうえで、適切に売上計上の妥当性をコメントできている | I8: 対応する売上高に実態があるかどうかの確認 | J8: =COUNTIF(チェックポイント!$I:$I,A8) -> 0 | K8: =SUMIF(チェックポイント!$I:$I,A8,チェックポイント!$G:$G) -> 0
A9: 8 | B9: 5 | C9: =IFERROR(INDEX(自主点検項目!$B:$B,MATCH(B9,自主点検項目!$A:$A,0)),"") -> 異常取引の分析 | D9: 成果物 | E9: 1次レビュー | F9: 共通 | G9: レビュー項目 | H9: データソースと抽出条件（手順）の記録が成果物として提出されている | I9: 試算表との一致確認がなく、データソース・抽出手順も不明の資料は不備ありとする | J9: =COUNTIF(チェックポイント!$I:$I,A9) -> 1 | K9: =SUMIF(チェックポイント!$I:$I,A9,チェックポイント!$G:$G) -> 89
A10: 9 | B10: 5 | C10: =IFERROR(INDEX(自主点検項目!$B:$B,MATCH(B10,自主点検項目!$A:$A,0)),"") -> 異常取引の分析 | D10: 成果物 | E10: 1次レビュー | F10: 共通 | G10: レビュー項目 | H10: 25年4月~26年3月の全ての売上明細（マイナス含む）が提出されている（試算表との一致が確認できる） | I10: 網羅性の確認 | J10: =COUNTIF(チェックポイント!$I:$I,A10) -> 4 | K10: =SUMIF(チェックポイント!$I:$I,A10,チェックポイント!$G:$G) -> 159
A11: 10 | B11: 5 | C11: =IFERROR(INDEX(自主点検項目!$B:$B,MATCH(B11,自主点検項目!$A:$A,0)),"") -> 異常取引の分析 | D11: 成果物 | E11: 1次レビュー | F11: 共通 | G11: レビュー項目 | H11: マイナスの売上がある場合、売上計上の妥当性（収益認識基準を満たしているか）を検討したコメントが残されている | I11: No.5は根拠証憑が全件提出されていなくてもコメントがあればokとする。2次レビューにおいて、確認が必要なものだけ資料を依頼する | J11: =COUNTIF(チェックポイント!$I:$I,A11) -> 3 | K11: =SUMIF(チェックポイント!$I:$I,A11,チェックポイント!$G:$G) -> 14
A12: 11 | B12: 5 | C12: =IFERROR(INDEX(自主点検項目!$B:$B,MATCH(B12,自主点検項目!$A:$A,0)),"") -> 異常取引の分析 | D12: 収益認識基準の充足 | E12: 2次レビュー | F12: 共通 | G12: レビュー項目 | H12: マイナス売上の売上は収益認識基準を満たした売上計上である（例えば、リスクの高いマイナス取引については、根拠資料を確認したうえで①売上計上と②取消それぞれの観点で合理的なコメントが出来ているかの確認が必要） | J12: =COUNTIF(チェックポイント!$I:$I,A12) -> 2 | K12: =SUMIF(チェックポイント!$I:$I,A12,チェックポイント!$G:$G) -> 14
A13: 12 | B13: 5 | C13: =IFERROR(INDEX(自主点検項目!$B:$B,MATCH(B13,自主点検項目!$A:$A,0)),"") -> 異常取引の分析 | D13: 対応の適切性 | E13: 2次レビュー | F13: 共通 | G13: レビュー項目 | H13: 収益認識基準を満たさない売上計上の場合は、会計処理の顛末が記載されている | J13: =COUNTIF(チェックポイント!$I:$I,A13) -> 2 | K13: =SUMIF(チェックポイント!$I:$I,A13,チェックポイント!$G:$G) -> 7
A14: 13 | B14: 5 | C14: =IFERROR(INDEX(自主点検項目!$B:$B,MATCH(B14,自主点検項目!$A:$A,0)),"") -> 異常取引の分析 | D14: 閾値 （構成単位） | E14: 2次レビュー | F14: 構成単位 | G14: 選定方針 | H14: 当該項目は対象取引数が多いため、以下の閾値を設定し、レビュー対象を限定する 金額：2,000万円以上を対象。ただし、最低でも5件はレビューを実施 →当該閾値を設定しても件数が多い場合は自主点検Tまで連絡 | J14: =COUNTIF(チェックポイント!$I:$I,A14) -> 0 | K14: =SUMIF(チェックポイント!$I:$I,A14,チェックポイント!$G:$G) -> 0
A15: 14 | B15: 5 | C15: =IFERROR(INDEX(自主点検項目!$B:$B,MATCH(B15,自主点検項目!$A:$A,0)),"") -> 異常取引の分析 | D15: 閾値 （構成単位以外） | E15: 2次レビュー | F15: 構成単位以外 | G15: 選定方針 | H15: 当該項目は対象取引数が多いため、以下の閾値を設定し、レビュー対象を限定する 金額：2,000万円以上を対象。ただし、最低でも3件はレビューを実施 →当該閾値を設定しても件数が多い場合は自主点検Tまで連絡 | I15: 構成単位以外の最低件数は3件としている | J15: =COUNTIF(チェックポイント!$I:$I,A15) -> 0 | K15: =SUMIF(チェックポイント!$I:$I,A15,チェックポイント!$G:$G) -> 0
A16: 15 | B16: 5 | C16: =IFERROR(INDEX(自主点検項目!$B:$B,MATCH(B16,自主点検項目!$A:$A,0)),"") -> 異常取引の分析 | D16: 記入例 | E16: 2次レビュー | F16: 共通 | G16: 記入例 | H16: ①自主点検レビュー結果には、以下を記載 問題なしの場合→「特段異常なし。」 差し戻しの場合→「No.x、xxの取引について、リスクがあると判断（取引の詳細は成果物を参照）」 ②成果物には、取引ごとに以下の方針で記載（どれをレビュー対象としたのか） 問題なしの場合→「〇〇を確認し、売上計上は妥当である。また、取消理由についても妥当であることから、特段異常なし。」 差し戻しの場合→「取消理由に合理性がなく、〇〇を確認した結果、△△が不一致のため、売上計上にリスクがあり検討必要と判断」 ・〇〇は資料名 ・△△は数量、金額、計上日 | I16: ①はサマリのイメージ、②はどの取引をレビューしたのか、レビューの詳細を把握したい | J16: =COUNTIF(チェックポイント!$I:$I,A16) -> 0 | K16: =SUMIF(チェックポイント!$I:$I,A16,チェックポイント!$G:$G) -> 0
A17: 16 | B17: 6 | C17: =IFERROR(INDEX(自主点検項目!$B:$B,MATCH(B17,自主点検項目!$A:$A,0)),"") -> 売上の期末変動分析 | D17: 成果物 | E17: 1次レビュー | F17: 構成単位 | G17: レビュー項目 | H17: データソースと抽出条件（手順）の記録が成果物として提出されている | I17: 試算表との一致確認がなく、データソース・抽出手順も不明の資料は不備ありとする | J17: =COUNTIF(チェックポイント!$I:$I,A17) -> 2 | K17: =SUMIF(チェックポイント!$I:$I,A17,チェックポイント!$G:$G) -> 91
A18: 17 | B18: 6 | C18: =IFERROR(INDEX(自主点検項目!$B:$B,MATCH(B18,自主点検項目!$A:$A,0)),"") -> 売上の期末変動分析 | D18: 成果物 | E18: 1次レビュー | F18: 構成単位 | G18: レビュー項目 | H18: 網羅性が確認できる情報が記載又は提出されている（試算表との一致が確認できる） | I18: 網羅性の確認 | J18: =COUNTIF(チェックポイント!$I:$I,A18) -> 2 | K18: =SUMIF(チェックポイント!$I:$I,A18,チェックポイント!$G:$G) -> 88
A19: 18 | B19: 6 | C19: =IFERROR(INDEX(自主点検項目!$B:$B,MATCH(B19,自主点検項目!$A:$A,0)),"") -> 売上の期末変動分析 | D19: 成果物 | E19: 1次レビュー | F19: 構成単位 | G19: レビュー項目 | H19: 前年同期・前月比較ともに、10百万円の変動、かつ、20%以上の変動がある場合、増減コメントがされている | J19: =COUNTIF(チェックポイント!$I:$I,A19) -> 1 | K19: =SUMIF(チェックポイント!$I:$I,A19,チェックポイント!$G:$G) -> 9
A20: 19 | B20: 6 | C20: =IFERROR(INDEX(自主点検項目!$B:$B,MATCH(B20,自主点検項目!$A:$A,0)),"") -> 売上の期末変動分析 | D20: 成果物 | E20: 1次レビュー | F20: 構成単位 | G20: レビュー項目 | H20: 増減分析コメントにて、要因毎の影響金額を記載している（最低限、6割～7割程度） | J20: =COUNTIF(チェックポイント!$I:$I,A20) -> 2 | K20: =SUMIF(チェックポイント!$I:$I,A20,チェックポイント!$G:$G) -> 14
A21: 20 | B21: 6 | C21: =IFERROR(INDEX(自主点検項目!$B:$B,MATCH(B21,自主点検項目!$A:$A,0)),"") -> 売上の期末変動分析 | D21: 成果物 | E21: 1次レビュー | F21: 構成単位 | G21: レビュー項目 | H21: 特に四半期末月に上昇傾向があった場合に、根拠資料に基づいて売上計上の妥当性を検証している。また、検証した旨がコメントされている。 | J21: =COUNTIF(チェックポイント!$I:$I,A21) -> 3 | K21: =SUMIF(チェックポイント!$I:$I,A21,チェックポイント!$G:$G) -> 11
A22: 21 | B22: 6 | C22: =IFERROR(INDEX(自主点検項目!$B:$B,MATCH(B22,自主点検項目!$A:$A,0)),"") -> 売上の期末変動分析 | D22: 分析の妥当性 | E22: 2次レビュー | F22: 構成単位 | G22: レビュー項目 | H22: 増減分析コメントにて、増減内容の説明になっている | J22: =COUNTIF(チェックポイント!$I:$I,A22) -> 1 | K22: =SUMIF(チェックポイント!$I:$I,A22,チェックポイント!$G:$G) -> 2
A23: 22 | B23: 6 | C23: =IFERROR(INDEX(自主点検項目!$B:$B,MATCH(B23,自主点検項目!$A:$A,0)),"") -> 売上の期末変動分析 | D23: 分析の妥当性 | E23: 2次レビュー | F23: 構成単位 | G23: レビュー項目 | H23: 増減分析コメントにて、金額推移と整合した説明になっている | J23: =COUNTIF(チェックポイント!$I:$I,A23) -> 0 | K23: =SUMIF(チェックポイント!$I:$I,A23,チェックポイント!$G:$G) -> 0
A24: 23 | B24: 6 | C24: =IFERROR(INDEX(自主点検項目!$B:$B,MATCH(B24,自主点検項目!$A:$A,0)),"") -> 売上の期末変動分析 | D24: 成果物 | E24: 1次レビュー | F24: 構成単位以外 | G24: レビュー項目 | H24: データソースと抽出条件（手順）の記録が成果物として提出されている | I24: 試算表との一致確認がなく、データソース・抽出手順も不明の資料は不備ありとする | J24: =COUNTIF(チェックポイント!$I:$I,A24) -> 0 | K24: =SUMIF(チェックポイント!$I:$I,A24,チェックポイント!$G:$G) -> 0
A25: 24 | B25: 6 | C25: =IFERROR(INDEX(自主点検項目!$B:$B,MATCH(B25,自主点検項目!$A:$A,0)),"") -> 売上の期末変動分析 | D25: 成果物 | E25: 1次レビュー | F25: 構成単位以外 | G25: レビュー項目 | H25: 網羅性が確認できる情報が記載又は提出されている（試算表との一致が確認できる） | I25: 網羅性の確認 | J25: =COUNTIF(チェックポイント!$I:$I,A25) -> 0 | K25: =SUMIF(チェックポイント!$I:$I,A25,チェックポイント!$G:$G) -> 0
A26: 25 | B26: 6 | C26: =IFERROR(INDEX(自主点検項目!$B:$B,MATCH(B26,自主点検項目!$A:$A,0)),"") -> 売上の期末変動分析 | D26: 成果物 | E26: 1次レビュー | F26: 構成単位以外 | G26: レビュー項目 | H26: 前年同期・前月比較ともに、10百万円の変動、かつ、20%以上の変動がある場合、増減コメントがされている 特に四半期末月に上昇傾向があった場合に、増減分析コメントにて、要因を記載している | I26: 売上高・粗利に重要な変動があればコメントが記載されていることを確認する。10百万円の変動、かつ、20%以上の変動は1つの基準にはなるが、毎月の記載は不要とする。四半期末月において、10百万円の変動、かつ、20%以上の変動があった場合には増減コメントを記載する。 | J26: =COUNTIF(チェックポイント!$I:$I,A26) -> 0 | K26: =SUMIF(チェックポイント!$I:$I,A26,チェックポイント!$G:$G) -> 0
A27: 26 | B27: 6 | C27: =IFERROR(INDEX(自主点検項目!$B:$B,MATCH(B27,自主点検項目!$A:$A,0)),"") -> 売上の期末変動分析 | D27: 分析の妥当性 | E27: 2次レビュー | F27: 構成単位以外 | G27: レビュー項目 | H27: 増減分析コメントにて、増減内容の説明になっている | I27: 定量的な記載は必ずしも必要とはしない。定性的に増減内容の説明になっていれば（矛盾がなければ）okとする。 | J27: =COUNTIF(チェックポイント!$I:$I,A27) -> 0 | K27: =SUMIF(チェックポイント!$I:$I,A27,チェックポイント!$G:$G) -> 0
A28: 27 | B28: 8 | C28: =IFERROR(INDEX(自主点検項目!$B:$B,MATCH(B28,自主点検項目!$A:$A,0)),"") -> 売上のカットオフテスト | D28: 成果物 | E28: 1次レビュー | F28: 共通 | G28: レビュー項目 | H28: データソースと抽出条件（手順）の記録が成果物として提出されている | I28: 試算表との一致確認がなく、データソース・抽出手順も不明の資料は不備ありとする | J28: =COUNTIF(チェックポイント!$I:$I,A28) -> 2 | K28: =SUMIF(チェックポイント!$I:$I,A28,チェックポイント!$G:$G) -> 76
A29: 28 | B29: 8 | C29: =IFERROR(INDEX(自主点検項目!$B:$B,MATCH(B29,自主点検項目!$A:$A,0)),"") -> 売上のカットオフテスト | D29: 成果物 | E29: 1次レビュー | F29: 共通 | G29: レビュー項目 | H29: 26年3月単月の全ての売上明細が提出されている（試算表との一致が確認できる） | I29: 網羅性の確認 | J29: =COUNTIF(チェックポイント!$I:$I,A29) -> 5 | K29: =SUMIF(チェックポイント!$I:$I,A29,チェックポイント!$G:$G) -> 104
A30: 29 | B30: 8 | C30: =IFERROR(INDEX(自主点検項目!$B:$B,MATCH(B30,自主点検項目!$A:$A,0)),"") -> 売上のカットオフテスト | D30: 成果物 | E30: 1次レビュー | F30: 共通 | G30: レビュー項目 | H30: 全ての明細に対して売上計上の妥当性（収益認識基準を満たしているか）を検討したコメントが残されている | J30: =COUNTIF(チェックポイント!$I:$I,A30) -> 4 | K30: =SUMIF(チェックポイント!$I:$I,A30,チェックポイント!$G:$G) -> 36
A31: 30 | B31: 8 | C31: =IFERROR(INDEX(自主点検項目!$B:$B,MATCH(B31,自主点検項目!$A:$A,0)),"") -> 売上のカットオフテスト | D31: 根拠資料 | E31: 1次レビュー | F31: 共通 | G31: レビュー項目 | H31: 1,000万円以上の取引について、根拠資料が提出されている | J31: =COUNTIF(チェックポイント!$I:$I,A31) -> 3 | K31: =SUMIF(チェックポイント!$I:$I,A31,チェックポイント!$G:$G) -> 11
A32: 31 | B32: 8 | C32: =IFERROR(INDEX(自主点検項目!$B:$B,MATCH(B32,自主点検項目!$A:$A,0)),"") -> 売上のカットオフテスト | D32: 根拠資料の信頼性 | E32: 2次レビュー | F32: 共通 | G32: レビュー項目 | H32: 根拠資料は第三者により作成または承認されたものである | J32: =COUNTIF(チェックポイント!$I:$I,A32) -> 1 | K32: =SUMIF(チェックポイント!$I:$I,A32,チェックポイント!$G:$G) -> 1
A33: 32 | B33: 8 | C33: =IFERROR(INDEX(自主点検項目!$B:$B,MATCH(B33,自主点検項目!$A:$A,0)),"") -> 売上のカットオフテスト | D33: 収益認識基準の充足 | E33: 2次レビュー | F33: 共通 | G33: レビュー項目 | H33: 収益認識基準を満たした売上計上である（根拠資料により、製品・サービス、数量が確認できる） | J33: =COUNTIF(チェックポイント!$I:$I,A33) -> 1 | K33: =SUMIF(チェックポイント!$I:$I,A33,チェックポイント!$G:$G) -> 1
A34: 33 | B34: 8 | C34: =IFERROR(INDEX(自主点検項目!$B:$B,MATCH(B34,自主点検項目!$A:$A,0)),"") -> 売上のカットオフテスト | D34: 収益認識基準の充足 | E34: 2次レビュー | F34: 共通 | G34: レビュー項目 | H34: 収益認識基準を満たした売上計上である（根拠資料により、売上計上日の妥当性が確認できる） | I34: 分割売上、未検収売上がないかチェック | J34: =COUNTIF(チェックポイント!$I:$I,A34) -> 0 | K34: =SUMIF(チェックポイント!$I:$I,A34,チェックポイント!$G:$G) -> 0
A35: 34 | B35: 8 | C35: =IFERROR(INDEX(自主点検項目!$B:$B,MATCH(B35,自主点検項目!$A:$A,0)),"") -> 売上のカットオフテスト | D35: 対応の適切性 | E35: 2次レビュー | F35: 共通 | G35: レビュー項目 | H35: 収益認識基準を満たさない売上計上の場合は、売上計上の可否を検討し、会計処理の顛末が記載されている | J35: =COUNTIF(チェックポイント!$I:$I,A35) -> 0 | K35: =SUMIF(チェックポイント!$I:$I,A35,チェックポイント!$G:$G) -> 0
A36: 35 | B36: 8 | C36: =IFERROR(INDEX(自主点検項目!$B:$B,MATCH(B36,自主点検項目!$A:$A,0)),"") -> 売上のカットオフテスト | D36: 閾値 （構成単位） | E36: 2次レビュー | F36: 構成単位 | G36: 選定方針 | H36: 当該項目は対象取引数が多いため、以下の閾値を設定し、レビュー対象を限定する 金額：2,000万円以上を対象。ただし、最低でも5件はレビューを実施 →当該閾値を設定しても件数が多い場合は自主点検Tまで連絡 | J36: =COUNTIF(チェックポイント!$I:$I,A36) -> 0 | K36: =SUMIF(チェックポイント!$I:$I,A36,チェックポイント!$G:$G) -> 0
A37: 36 | B37: 8 | C37: =IFERROR(INDEX(自主点検項目!$B:$B,MATCH(B37,自主点検項目!$A:$A,0)),"") -> 売上のカットオフテスト | D37: 閾値 （構成単位以外） | E37: 2次レビュー | F37: 構成単位以外 | G37: 選定方針 | H37: 当該項目は対象取引数が多いため、以下の閾値を設定し、レビュー対象を限定する 金額：2,000万円以上を対象。ただし、最低でも3件はレビューを実施 →当該閾値を設定しても件数が多い場合は自主点検Tまで連絡 | I37: 最低件数は3件としている | J37: =COUNTIF(チェックポイント!$I:$I,A37) -> 0 | K37: =SUMIF(チェックポイント!$I:$I,A37,チェックポイント!$G:$G) -> 0
A38: 37 | B38: 8 | C38: =IFERROR(INDEX(自主点検項目!$B:$B,MATCH(B38,自主点検項目!$A:$A,0)),"") -> 売上のカットオフテスト | D38: 記入例 | E38: 2次レビュー | F38: 共通 | G38: 記入例 | H38: ①自主点検レビュー結果には、以下を記載 問題なしの場合→「特段異常なし。」 差し戻しの場合→「No.x、xx、xxxの取引について、リスクがあり検討必要と判断（取引の詳細は成果物を参照）」 ②成果物には、取引ごとに以下の方針で記載（どれをレビュー対象としたのか） 問題なしの場合→「〇〇と数量、金額、計上日が一致しており、特段異常なし。」 差し戻しの場合→「〇〇を確認した結果、△△が不一致のため、リスクがあり検討必要と判断」 ・〇〇は資料名 ・△△は数量、金額、計上日 | I38: ①はサマリのイメージ、②はどの取引をレビューしたのか、レビューの詳細を把握したい | J38: =COUNTIF(チェックポイント!$I:$I,A38) -> 0 | K38: =SUMIF(チェックポイント!$I:$I,A38,チェックポイント!$G:$G) -> 0
A39: 38 | B39: 9 | C39: =IFERROR(INDEX(自主点検項目!$B:$B,MATCH(B39,自主点検項目!$A:$A,0)),"") -> 長期請負工事案件の洗い出し | D39: 成果物 | E39: 1次レビュー | F39: 共通 | G39: レビュー項目 | H39: データソースと抽出条件（手順）の記録が成果物として提出されている | I39: 試算表との一致確認がなく、データソース・抽出手順も不明の資料は不備ありとする | J39: =COUNTIF(チェックポイント!$I:$I,A39) -> 2 | K39: =SUMIF(チェックポイント!$I:$I,A39,チェックポイント!$G:$G) -> 9
A40: 39 | B40: 9 | C40: =IFERROR(INDEX(自主点検項目!$B:$B,MATCH(B40,自主点検項目!$A:$A,0)),"") -> 長期請負工事案件の洗い出し | D40: 成果物 | E40: 1次レビュー | F40: 共通 | G40: レビュー項目 | H40: 網羅性が確認できる情報が記載又は提出されている（例：PKGの進行基準売上との一致） | I40: 網羅性の確認 | J40: =COUNTIF(チェックポイント!$I:$I,A40) -> 2 | K40: =SUMIF(チェックポイント!$I:$I,A40,チェックポイント!$G:$G) -> 4
...

Sheet チェックポイント
A1: No | B1: 自主点検項目No | C1: 自主点検項目名 | D1: 提出物No | E1: 提出物名 | F1: チェックポイント内容 | G1: 発生件数 | H1: 関連会社数 | I1: レビュー項目No | J1: カテゴリ | K1: レビュー区分 | L1: レビュー項目 | M1: 確認 | N1: 該当なし | O1: 非該当・未確認の理由 | P1: 備考
A2: 1 | B2: 4 | C2: =IFERROR(INDEX(自主点検項目!$B:$B,MATCH(B2,自主点検項目!$A:$A,0)),"") -> 滞留債権の分析 | D2: 15 | E2: =IFERROR(INDEX(提出物!$D:$D,MATCH(D2,提出物!$A:$A,0)),"") -> 売掛金明細・試算表の一致 | F2: 成果物の作成に用いたデータソースと抽出条件（手順）の記録（画面コピー等）が提出されているか。 | G2: =COUNTIF('チェックポイント-問合せ・差戻し事例対応表'!$B:$B,A2) -> 68 | H2: =SUMPRODUCT(('チェックポイント-問合せ・差戻し事例対応表'!$B$2:$B$5000=A2)*('チェックポイント-問合せ・差戻し事例対応表'!$I$2:$I$5000<>"")/(COUNTIFS('チェックポイント-問合せ・差戻し事例対応表'!$B$2:$B$5000,'チェックポイント-問合せ・差戻し事例対応表'!$B$2:$B$5000,'チェックポイント-問合せ・差戻し事例対応表'!$I$2:$I$5000,'チェックポイント-問合せ・差戻し事例対応表'!$I$2:$I$5000)+('チェックポイント-問合せ・差戻し事例対応表'!$I$2:$I$5000=""))) -> 62 | I2: 1 | J2: =IFERROR(INDEX(レビュー指針!$D:$D,MATCH(I2,レビュー指針!$A:$A,0)),"") -> 成果物 | K2: =IFERROR(INDEX(レビュー指針!$E:$E,MATCH(I2,レビュー指針!$A:$A,0)),"") -> 1次レビュー | L2: =IFERROR(INDEX(レビュー指針!$H:$H,MATCH(I2,レビュー指針!$A:$A,0)),"") -> データソースと抽出条件（手順）の記録が成果物として提出されている | P2: Stage2精査 / 複合問合せを分割（網羅性は別CPへ） / 自主点検QA由来 / 件数57 / 要文言整備
A3: 7 | B3: 4 | C3: =IFERROR(INDEX(自主点検項目!$B:$B,MATCH(B3,自主点検項目!$A:$A,0)),"") -> 滞留債権の分析 | D3: 共通 | E3: =IFERROR(INDEX(提出物!$D:$D,MATCH(D3,提出物!$A:$A,0)),"") | F3: 成果物の作成に用いたデータソースと抽出条件（手順）の記録（画面コピー等）が提出されているか。 | G3: =COUNTIF('チェックポイント-問合せ・差戻し事例対応表'!$B:$B,A3) -> 3 | H3: =SUMPRODUCT(('チェックポイント-問合せ・差戻し事例対応表'!$B$2:$B$5000=A3)*('チェックポイント-問合せ・差戻し事例対応表'!$I$2:$I$5000<>"")/(COUNTIFS('チェックポイント-問合せ・差戻し事例対応表'!$B$2:$B$5000,'チェックポイント-問合せ・差戻し事例対応表'!$B$2:$B$5000,'チェックポイント-問合せ・差戻し事例対応表'!$I$2:$I$5000,'チェックポイント-問合せ・差戻し事例対応表'!$I$2:$I$5000)+('チェックポイント-問合せ・差戻し事例対応表'!$I$2:$I$5000=""))) -> 3 | I3: 1 | J3: =IFERROR(INDEX(レビュー指針!$D:$D,MATCH(I3,レビュー指針!$A:$A,0)),"") -> 成果物 | K3: =IFERROR(INDEX(レビュー指針!$E:$E,MATCH(I3,レビュー指針!$A:$A,0)),"") -> 1次レビュー | L3: =IFERROR(INDEX(レビュー指針!$H:$H,MATCH(I3,レビュー指針!$A:$A,0)),"") -> データソースと抽出条件（手順）の記録が成果物として提出されている | P3: Stage2精査 / データソースチェック（英文） / 自主点検QA由来 / 件数3 / 要文言整備
A4: 8 | B4: 4 | C4: =IFERROR(INDEX(自主点検項目!$B:$B,MATCH(B4,自主点検項目!$A:$A,0)),"") -> 滞留債権の分析 | D4: 共通 | E4: =IFERROR(INDEX(提出物!$D:$D,MATCH(D4,提出物!$A:$A,0)),"") | F4: 期末時点で滞留している債権について、取引発生日・回収予定日・最新の回収予定日（回収遅延理由）が記載されているか。 | G4: =COUNTIF('チェックポイント-問合せ・差戻し事例対応表'!$B:$B,A4) -> 13 | H4: =SUMPRODUCT(('チェックポイント-問合せ・差戻し事例対応表'!$B$2:$B$5000=A4)*('チェックポイント-問合せ・差戻し事例対応表'!$I$2:$I$5000<>"")/(COUNTIFS('チェックポイント-問合せ・差戻し事例対応表'!$B$2:$B$5000,'チェックポイント-問合せ・差戻し事例対応表'!$B$2:$B$5000,'チェックポイント-問合せ・差戻し事例対応表'!$I$2:$I$5000,'チェックポイント-問合せ・差戻し事例対応表'!$I$2:$I$5000)+('チェックポイント-問合せ・差戻し事例対応表'!$I$2:$I$5000=""))) -> 11 | I4: 3 | J4: =IFERROR(INDEX(レビュー指針!$D:$D,MATCH(I4,レビュー指針!$A:$A,0)),"") -> 成果物 | K4: =IFERROR(INDEX(レビュー指針!$E:$E,MATCH(I4,レビュー指針!$A:$A,0)),"") -> 1次レビュー | L4: =IFERROR(INDEX(レビュー指針!$H:$H,MATCH(I4,レビュー指針!$A:$A,0)),"") -> 回収が遅延している債権全てにつき、回収遅延理由が記載されている | P4: Stage2精査 / 回収遅延理由 / 自主点検QA由来 / 件数2 / 要文言整備
A5: 9 | B5: 4 | C5: =IFERROR(INDEX(自主点検項目!$B:$B,MATCH(B5,自主点検項目!$A:$A,0)),"") -> 滞留債権の分析 | D5: 共通 | E5: =IFERROR(INDEX(提出物!$D:$D,MATCH(D5,提出物!$A:$A,0)),"") | F5: 回収遅延理由について部門責任者等の適切な承認を得ていることを示す資料が提出されているか。 | G5: =COUNTIF('チェックポイント-問合せ・差戻し事例対応表'!$B:$B,A5) -> 2 | H5: =SUMPRODUCT(('チェックポイント-問合せ・差戻し事例対応表'!$B$2:$B$5000=A5)*('チェックポイント-問合せ・差戻し事例対応表'!$I$2:$I$5000<>"")/(COUNTIFS('チェックポイント-問合せ・差戻し事例対応表'!$B$2:$B$5000,'チェックポイント-問合せ・差戻し事例対応表'!$B$2:$B$5000,'チェックポイント-問合せ・差戻し事例対応表'!$I$2:$I$5000,'チェックポイント-問合せ・差戻し事例対応表'!$I$2:$I$5000)+('チェックポイント-問合せ・差戻し事例対応表'!$I$2:$I$5000=""))) -> 2 | I5: 4 | J5: =IFERROR(INDEX(レビュー指針!$D:$D,MATCH(I5,レビュー指針!$A:$A,0)),"") -> 成果物 | K5: =IFERROR(INDEX(レビュー指針!$E:$E,MATCH(I5,レビュー指針!$A:$A,0)),"") -> 1次レビュー | L5: =IFERROR(INDEX(レビュー指針!$H:$H,MATCH(I5,レビュー指針!$A:$A,0)),"") -> 回収遅延理由について、部門責任者等の適切な承認者の承認を得ている | P5: Stage2精査 / 承認 / 自主点検QA由来 / 件数2 / 要文言整備
A6: 11 | B6: 5 | C6: =IFERROR(INDEX(自主点検項目!$B:$B,MATCH(B6,自主点検項目!$A:$A,0)),"") -> 異常取引の分析 | D6: 20 | E6: =IFERROR(INDEX(提出物!$D:$D,MATCH(D6,提出物!$A:$A,0)),"") -> データソース・抽出条件 | F6: 成果物の作成に用いたデータソースと抽出条件（手順）の記録（画面コピー等）が提出されているか。 | G6: =COUNTIF('チェックポイント-問合せ・差戻し事例対応表'!$B:$B,A6) -> 89 | H6: =SUMPRODUCT(('チェックポイント-問合せ・差戻し事例対応表'!$B$2:$B$5000=A6)*('チェックポイント-問合せ・差戻し事例対応表'!$I$2:$I$5000<>"")/(COUNTIFS('チェックポイント-問合せ・差戻し事例対応表'!$B$2:$B$5000,'チェックポイント-問合せ・差戻し事例対応表'!$B$2:$B$5000,'チェックポイント-問合せ・差戻し事例対応表'!$I$2:$I$5000,'チェックポイント-問合せ・差戻し事例対応表'!$I$2:$I$5000)+('チェックポイント-問合せ・差戻し事例対応表'!$I$2:$I$5000=""))) -> 80 | I6: 8 | J6: =IFERROR(INDEX(レビュー指針!$D:$D,MATCH(I6,レビュー指針!$A:$A,0)),"") -> 成果物 | K6: =IFERROR(INDEX(レビュー指針!$E:$E,MATCH(I6,レビュー指針!$A:$A,0)),"") -> 1次レビュー | L6: =IFERROR(INDEX(レビュー指針!$H:$H,MATCH(I6,レビュー指針!$A:$A,0)),"") -> データソースと抽出条件（手順）の記録が成果物として提出されている | P6: Stage2精査 / 複合問合せを分割（網羅性は別CPへ） / 自主点検QA由来 / 件数68 / 要文言整備
A7: 22 | B7: 5 | C7: =IFERROR(INDEX(自主点検項目!$B:$B,MATCH(B7,自主点検項目!$A:$A,0)),"") -> 異常取引の分析 | D7: 20 | E7: =IFERROR(INDEX(提出物!$D:$D,MATCH(D7,提出物!$A:$A,0)),"") -> データソース・抽出条件 | F7: 全ての売上明細を提出のうえ、マイナス売上について売上計上の妥当性（収益認識基準の充足）のコメントが記載されているか。 | G7: =COUNTIF('チェックポイント-問合せ・差戻し事例対応表'!$B:$B,A7) -> 2 | H7: =SUMPRODUCT(('チェックポイント-問合せ・差戻し事例対応表'!$B$2:$B$5000=A7)*('チェックポイント-問合せ・差戻し事例対応表'!$I$2:$I$5000<>"")/(COUNTIFS('チェックポイント-問合せ・差戻し事例対応表'!$B$2:$B$5000,'チェックポイント-問合せ・差戻し事例対応表'!$B$2:$B$5000,'チェックポイント-問合せ・差戻し事例対応表'!$I$2:$I$5000,'チェックポイント-問合せ・差戻し事例対応表'!$I$2:$I$5000)+('チェックポイント-問合せ・差戻し事例対応表'!$I$2:$I$5000=""))) -> 2 | I7: 10 | J7: =IFERROR(INDEX(レビュー指針!$D:$D,MATCH(I7,レビュー指針!$A:$A,0)),"") -> 成果物 | K7: =IFERROR(INDEX(レビュー指針!$E:$E,MATCH(I7,レビュー指針!$A:$A,0)),"") -> 1次レビュー | L7: =IFERROR(INDEX(レビュー指針!$H:$H,MATCH(I7,レビュー指針!$A:$A,0)),"") -> マイナスの売上がある場合、売上計上の妥当性（収益認識基準を満たしているか）を検討したコメントが残されている | P7: Stage2精査 / マイナス妥当性 / 自主点検QA由来 / 件数2 / 要文言整備
A8: 25 | B8: 5 | C8: =IFERROR(INDEX(自主点検項目!$B:$B,MATCH(B8,自主点検項目!$A:$A,0)),"") -> 異常取引の分析 | D8: 21 | E8: =IFERROR(INDEX(提出物!$D:$D,MATCH(D8,提出物!$A:$A,0)),"") -> マイナス取引の根拠資料 | F8: マイナス売上について売上計上の妥当性（収益認識基準の充足）を検討したコメントが提出されているか（翌期4月分含む）。 | G8: =COUNTIF('チェックポイント-問合せ・差戻し事例対応表'!$B:$B,A8) -> 6 | H8: =SUMPRODUCT(('チェックポイント-問合せ・差戻し事例対応表'!$B$2:$B$5000=A8)*('チェックポイント-問合せ・差戻し事例対応表'!$I$2:$I$5000<>"")/(COUNTIFS('チェックポイント-問合せ・差戻し事例対応表'!$B$2:$B$5000,'チェックポイント-問合せ・差戻し事例対応表'!$B$2:$B$5000,'チェックポイント-問合せ・差戻し事例対応表'!$I$2:$I$5000,'チェックポイント-問合せ・差戻し事例対応表'!$I$2:$I$5000)+('チェックポイント-問合せ・差戻し事例対応表'!$I$2:$I$5000=""))) -> 6 | I8: 10 | J8: =IFERROR(INDEX(レビュー指針!$D:$D,MATCH(I8,レビュー指針!$A:$A,0)),"") -> 成果物 | K8: =IFERROR(INDEX(レビュー指針!$E:$E,MATCH(I8,レビュー指針!$A:$A,0)),"") -> 1次レビュー | L8: =IFERROR(INDEX(レビュー指針!$H:$H,MATCH(I8,レビュー指針!$A:$A,0)),"") -> マイナスの売上がある場合、売上計上の妥当性（収益認識基準を満たしているか）を検討したコメントが残されている | P8: Stage2精査 / マイナス妥当性 / 自主点検QA由来 / 件数6 / 要文言整備
A9: 26 | B9: 5 | C9: =IFERROR(INDEX(自主点検項目!$B:$B,MATCH(B9,自主点検項目!$A:$A,0)),"") -> 異常取引の分析 | D9: 共通 | E9: =IFERROR(INDEX(提出物!$D:$D,MATCH(D9,提出物!$A:$A,0)),"") | F9: 25年4月〜26年3月の全売上明細（マイナス含む）が提出され、試算表と一致することが確認できるか。 | G9: =COUNTIF('チェックポイント-問合せ・差戻し事例対応表'!$B:$B,A9) -> 12 | H9: =SUMPRODUCT(('チェックポイント-問合せ・差戻し事例対応表'!$B$2:$B$5000=A9)*('チェックポイント-問合せ・差戻し事例対応表'!$I$2:$I$5000<>"")/(COUNTIFS('チェックポイント-問合せ・差戻し事例対応表'!$B$2:$B$5000,'チェックポイント-問合せ・差戻し事例対応表'!$B$2:$B$5000,'チェックポイント-問合せ・差戻し事例対応表'!$I$2:$I$5000,'チェックポイント-問合せ・差戻し事例対応表'!$I$2:$I$5000)+('チェックポイント-問合せ・差戻し事例対応表'!$I$2:$I$5000=""))) -> 11 | I9: 9 | J9: =IFERROR(INDEX(レビュー指針!$D:$D,MATCH(I9,レビュー指針!$A:$A,0)),"") -> 成果物 | K9: =IFERROR(INDEX(レビュー指針!$E:$E,MATCH(I9,レビュー指針!$A:$A,0)),"") -> 1次レビュー | L9: =IFERROR(INDEX(レビュー指針!$H:$H,MATCH(I9,レビュー指針!$A:$A,0)),"") -> 25年4月~26年3月の全ての売上明細（マイナス含む）が提出されている（試算表との一致が確認できる） | P9: Stage2精査 / 網羅性 / 自主点検QA由来 / 件数2 / 要文言整備
A10: 27 | B10: 5 | C10: =IFERROR(INDEX(自主点検項目!$B:$B,MATCH(B10,自主点検項目!$A:$A,0)),"") -> 異常取引の分析 | D10: 共通 | E10: =IFERROR(INDEX(提出物!$D:$D,MATCH(D10,提出物!$A:$A,0)),"") | F10: マイナス売上について売上計上の妥当性（収益認識基準の充足）を検討したコメント・根拠が提出されているか。 | G10: =COUNTIF('チェックポイント-問合せ・差戻し事例対応表'!$B:$B,A10) -> 6 | H10: =SUMPRODUCT(('チェックポイント-問合せ・差戻し事例対応表'!$B$2:$B$5000=A10)*('チェックポイント-問合せ・差戻し事例対応表'!$I$2:$I$5000<>"")/(COUNTIFS('チェックポイント-問合せ・差戻し事例対応表'!$B$2:$B$5000,'チェックポイント-問合せ・差戻し事例対応表'!$B$2:$B$5000,'チェックポイント-問合せ・差戻し事例対応表'!$I$2:$I$5000,'チェックポイント-問合せ・差戻し事例対応表'!$I$2:$I$5000)+('チェックポイント-問合せ・差戻し事例対応表'!$I$2:$I$5000=""))) -> 6 | I10: 10 | J10: =IFERROR(INDEX(レビュー指針!$D:$D,MATCH(I10,レビュー指針!$A:$A,0)),"") -> 成果物 | K10: =IFERROR(INDEX(レビュー指針!$E:$E,MATCH(I10,レビュー指針!$A:$A,0)),"") -> 1次レビュー | L10: =IFERROR(INDEX(レビュー指針!$H:$H,MATCH(I10,レビュー指針!$A:$A,0)),"") -> マイナスの売上がある場合、売上計上の妥当性（収益認識基準を満たしているか）を検討したコメントが残されている | P10: Stage2精査 / マイナス妥当性 / 自主点検QA由来 / 件数2 / 要文言整備
A11: 31 | B11: 6 | C11: =IFERROR(INDEX(自主点検項目!$B:$B,MATCH(B11,自主点検項目!$A:$A,0)),"") -> 売上の期末変動分析 | D11: 22 | E11: =IFERROR(INDEX(提出物!$D:$D,MATCH(D11,提出物!$A:$A,0)),"") -> 月次の売上・粗利推移データ | F11: 前年同期・前月比較で10百万円かつ20%以上の変動がある場合、増減理由のコメントが記載されているか。 | G11: =COUNTIF('チェックポイント-問合せ・差戻し事例対応表'!$B:$B,A11) -> 9 | H11: =SUMPRODUCT(('チェックポイント-問合せ・差戻し事例対応表'!$B$2:$B$5000=A11)*('チェックポイント-問合せ・差戻し事例対応表'!$I$2:$I$5000<>"")/(COUNTIFS('チェックポイント-問合せ・差戻し事例対応表'!$B$2:$B$5000,'チェックポイント-問合せ・差戻し事例対応表'!$B$2:$B$5000,'チェックポイント-問合せ・差戻し事例対応表'!$I$2:$I$5000,'チェックポイント-問合せ・差戻し事例対応表'!$I$2:$I$5000)+('チェックポイント-問合せ・差戻し事例対応表'!$I$2:$I$5000=""))) -> 7 | I11: 18 | J11: =IFERROR(INDEX(レビュー指針!$D:$D,MATCH(I11,レビュー指針!$A:$A,0)),"") -> 成果物 | K11: =IFERROR(INDEX(レビュー指針!$E:$E,MATCH(I11,レビュー指針!$A:$A,0)),"") -> 1次レビュー | L11: =IFERROR(INDEX(レビュー指針!$H:$H,MATCH(I11,レビュー指針!$A:$A,0)),"") -> 前年同期・前月比較ともに、10百万円の変動、かつ、20%以上の変動がある場合、増減コメントがされている | P11: Stage2精査 / 増減コメント / 自主点検QA由来 / 件数4 / 要文言整備
A12: 34 | B12: 6 | C12: =IFERROR(INDEX(自主点検項目!$B:$B,MATCH(B12,自主点検項目!$A:$A,0)),"") -> 売上の期末変動分析 | D12: 22 | E12: =IFERROR(INDEX(提出物!$D:$D,MATCH(D12,提出物!$A:$A,0)),"") -> 月次の売上・粗利推移データ | F12: 増減分析コメントに、要因ごとの影響金額が記載されているか。 | G12: =COUNTIF('チェックポイント-問合せ・差戻し事例対応表'!$B:$B,A12) -> 12 | H12: =SUMPRODUCT(('チェックポイント-問合せ・差戻し事例対応表'!$B$2:$B$5000=A12)*('チェックポイント-問合せ・差戻し事例対応表'!$I$2:$I$5000<>"")/(COUNTIFS('チェックポイント-問合せ・差戻し事例対応表'!$B$2:$B$5000,'チェックポイント-問合せ・差戻し事例対応表'!$B$2:$B$5000,'チェックポイント-問合せ・差戻し事例対応表'!$I$2:$I$5000,'チェックポイント-問合せ・差戻し事例対応表'!$I$2:$I$5000)+('チェックポイント-問合せ・差戻し事例対応表'!$I$2:$I$5000=""))) -> 11 | I12: 19 | J12: =IFERROR(INDEX(レビュー指針!$D:$D,MATCH(I12,レビュー指針!$A:$A,0)),"") -> 成果物 | K12: =IFERROR(INDEX(レビュー指針!$E:$E,MATCH(I12,レビュー指針!$A:$A,0)),"") -> 1次レビュー | L12: =IFERROR(INDEX(レビュー指針!$H:$H,MATCH(I12,レビュー指針!$A:$A,0)),"") -> 増減分析コメントにて、要因毎の影響金額を記載している（最低限、6割～7割程度） | P12: Stage2精査 / 要因別影響金額 / 自主点検QA由来 / 件数2 / 要文言整備
A13: 35 | B13: 6 | C13: =IFERROR(INDEX(自主点検項目!$B:$B,MATCH(B13,自主点検項目!$A:$A,0)),"") -> 売上の期末変動分析 | D13: 23 | E13: =IFERROR(INDEX(提出物!$D:$D,MATCH(D13,提出物!$A:$A,0)),"") -> データソース・抽出条件 | F13: 成果物の作成に用いたデータソースと抽出条件（手順）の記録（画面コピー等）が提出されているか。 | G13: =COUNTIF('チェックポイント-問合せ・差戻し事例対応表'!$B:$B,A13) -> 86 | H13: =SUMPRODUCT(('チェックポイント-問合せ・差戻し事例対応表'!$B$2:$B$5000=A13)*('チェックポイント-問合せ・差戻し事例対応表'!$I$2:$I$5000<>"")/(COUNTIFS('チェックポイント-問合せ・差戻し事例対応表'!$B$2:$B$5000,'チェックポイント-問合せ・差戻し事例対応表'!$B$2:$B$5000,'チェックポイント-問合せ・差戻し事例対応表'!$I$2:$I$5000,'チェックポイント-問合せ・差戻し事例対応表'!$I$2:$I$5000)+('チェックポイント-問合せ・差戻し事例対応表'!$I$2:$I$5000=""))) -> 83 | I13: 16 | J13: =IFERROR(INDEX(レビュー指針!$D:$D,MATCH(I13,レビュー指針!$A:$A,0)),"") -> 成果物 | K13: =IFERROR(INDEX(レビュー指針!$E:$E,MATCH(I13,レビュー指針!$A:$A,0)),"") -> 1次レビュー | L13: =IFERROR(INDEX(レビュー指針!$H:$H,MATCH(I13,レビュー指針!$A:$A,0)),"") -> データソースと抽出条件（手順）の記録が成果物として提出されている | P13: Stage2精査 / 複合問合せを分割（網羅性は別CPへ） / 自主点検QA由来 / 件数82 / 要文言整備
A14: 38 | B14: 6 | C14: =IFERROR(INDEX(自主点検項目!$B:$B,MATCH(B14,自主点検項目!$A:$A,0)),"") -> 売上の期末変動分析 | D14: 23 | E14: =IFERROR(INDEX(提出物!$D:$D,MATCH(D14,提出物!$A:$A,0)),"") -> データソース・抽出条件 | F14: 進行基準・完成基準の差異や大口請負案件について、増減内容の合理的な説明がされているか。 | G14: =COUNTIF('チェックポイント-問合せ・差戻し事例対応表'!$B:$B,A14) -> 2 | H14: =SUMPRODUCT(('チェックポイント-問合せ・差戻し事例対応表'!$B$2:$B$5000=A14)*('チェックポイント-問合せ・差戻し事例対応表'!$I$2:$I$5000<>"")/(COUNTIFS('チェックポイント-問合せ・差戻し事例対応表'!$B$2:$B$5000,'チェックポイント-問合せ・差戻し事例対応表'!$B$2:$B$5000,'チェックポイント-問合せ・差戻し事例対応表'!$I$2:$I$5000,'チェックポイント-問合せ・差戻し事例対応表'!$I$2:$I$5000)+('チェックポイント-問合せ・差戻し事例対応表'!$I$2:$I$5000=""))) -> 2 | I14: 21 | J14: =IFERROR(INDEX(レビュー指針!$D:$D,MATCH(I14,レビュー指針!$A:$A,0)),"") -> 分析の妥当性 | K14: =IFERROR(INDEX(レビュー指針!$E:$E,MATCH(I14,レビュー指針!$A:$A,0)),"") -> 2次レビュー | L14: =IFERROR(INDEX(レビュー指針!$H:$H,MATCH(I14,レビュー指針!$A:$A,0)),"") -> 増減分析コメントにて、増減内容の説明になっている | P14: Stage2精査 / 分析の妥当性 / 自主点検QA由来 / 件数2 / 要文言整備
A15: 39 | B15: 6 | C15: =IFERROR(INDEX(自主点検項目!$B:$B,MATCH(B15,自主点検項目!$A:$A,0)),"") -> 売上の期末変動分析 | D15: 共通 | E15: =IFERROR(INDEX(提出物!$D:$D,MATCH(D15,提出物!$A:$A,0)),"") | F15: 成果物の作成に用いたデータソースと抽出条件（手順）の記録（画面コピー等）が提出されているか。 | G15: =COUNTIF('チェックポイント-問合せ・差戻し事例対応表'!$B:$B,A15) -> 5 | H15: =SUMPRODUCT(('チェックポイント-問合せ・差戻し事例対応表'!$B$2:$B$5000=A15)*('チェックポイント-問合せ・差戻し事例対応表'!$I$2:$I$5000<>"")/(COUNTIFS('チェックポイント-問合せ・差戻し事例対応表'!$B$2:$B$5000,'チェックポイント-問合せ・差戻し事例対応表'!$B$2:$B$5000,'チェックポイント-問合せ・差戻し事例対応表'!$I$2:$I$5000,'チェックポイント-問合せ・差戻し事例対応表'!$I$2:$I$5000)+('チェックポイント-問合せ・差戻し事例対応表'!$I$2:$I$5000=""))) -> 5 | I15: 16 | J15: =IFERROR(INDEX(レビュー指針!$D:$D,MATCH(I15,レビュー指針!$A:$A,0)),"") -> 成果物 | K15: =IFERROR(INDEX(レビュー指針!$E:$E,MATCH(I15,レビュー指針!$A:$A,0)),"") -> 1次レビュー | L15: =IFERROR(INDEX(レビュー指針!$H:$H,MATCH(I15,レビュー指針!$A:$A,0)),"") -> データソースと抽出条件（手順）の記録が成果物として提出されている | P15: Stage2精査 / データソースチェック（英文問合せ）へ整形 / 自主点検QA由来 / 件数5 / 要文言整備
A16: 40 | B16: 6 | C16: =IFERROR(INDEX(自主点検項目!$B:$B,MATCH(B16,自主点検項目!$A:$A,0)),"") -> 売上の期末変動分析 | D16: 共通 | E16: =IFERROR(INDEX(提出物!$D:$D,MATCH(D16,提出物!$A:$A,0)),"") | F16: 粗利益（売上総利益）が損益計算書と一致しているか（数値の整合）。 | G16: =COUNTIF('チェックポイント-問合せ・差戻し事例対応表'!$B:$B,A16) -> 2 | H16: =SUMPRODUCT(('チェックポイント-問合せ・差戻し事例対応表'!$B$2:$B$5000=A16)*('チェックポイント-問合せ・差戻し事例対応表'!$I$2:$I$5000<>"")/(COUNTIFS('チェックポイント-問合せ・差戻し事例対応表'!$B$2:$B$5000,'チェックポイント-問合せ・差戻し事例対応表'!$B$2:$B$5000,'チェックポイント-問合せ・差戻し事例対応表'!$I$2:$I$5000,'チェックポイント-問合せ・差戻し事例対応表'!$I$2:$I$5000)+('チェックポイント-問合せ・差戻し事例対応表'!$I$2:$I$5000=""))) -> 1 | I16: 17 | J16: =IFERROR(INDEX(レビュー指針!$D:$D,MATCH(I16,レビュー指針!$A:$A,0)),"") -> 成果物 | K16: =IFERROR(INDEX(レビュー指針!$E:$E,MATCH(I16,レビュー指針!$A:$A,0)),"") -> 1次レビュー | L16: =IFERROR(INDEX(レビュー指針!$H:$H,MATCH(I16,レビュー指針!$A:$A,0)),"") -> 網羅性が確認できる情報が記載又は提出されている（試算表との一致が確認できる） | P16: Stage2精査 / 網羅性・整合 / 自主点検QA由来 / 件数2 / 要文言整備
A17: 41 | B17: 8 | C17: =IFERROR(INDEX(自主点検項目!$B:$B,MATCH(B17,自主点検項目!$A:$A,0)),"") -> 売上のカットオフテスト | D17: 28 | E17: =IFERROR(INDEX(提出物!$D:$D,MATCH(D17,提出物!$A:$A,0)),"") -> 売上明細データ | F17: 成果物の作成に用いたデータソースと抽出条件（手順）の記録（画面コピー等）が提出されているか。 | G17: =COUNTIF('チェックポイント-問合せ・差戻し事例対応表'!$B:$B,A17) -> 9 | H17: =SUMPRODUCT(('チェックポイント-問合せ・差戻し事例対応表'!$B$2:$B$5000=A17)*('チェックポイント-問合せ・差戻し事例対応表'!$I$2:$I$5000<>"")/(COUNTIFS('チェックポイント-問合せ・差戻し事例対応表'!$B$2:$B$5000,'チェックポイント-問合せ・差戻し事例対応表'!$B$2:$B$5000,'チェックポイント-問合せ・差戻し事例対応表'!$I$2:$I$5000,'チェックポイント-問合せ・差戻し事例対応表'!$I$2:$I$5000)+('チェックポイント-問合せ・差戻し事例対応表'!$I$2:$I$5000=""))) -> 8 | I17: 27 | J17: =IFERROR(INDEX(レビュー指針!$D:$D,MATCH(I17,レビュー指針!$A:$A,0)),"") -> 成果物 | K17: =IFERROR(INDEX(レビュー指針!$E:$E,MATCH(I17,レビュー指針!$A:$A,0)),"") -> 1次レビュー | L17: =IFERROR(INDEX(レビュー指針!$H:$H,MATCH(I17,レビュー指針!$A:$A,0)),"") -> データソースと抽出条件（手順）の記録が成果物として提出されている | P17: Stage2精査 / 複合問合せを分割（網羅性は別CPへ） / 自主点検QA由来 / 件数9 / 要文言整備
A18: 42 | B18: 8 | C18: =IFERROR(INDEX(自主点検項目!$B:$B,MATCH(B18,自主点検項目!$A:$A,0)),"") -> 売上のカットオフテスト | D18: 28 | E18: =IFERROR(INDEX(提出物!$D:$D,MATCH(D18,提出物!$A:$A,0)),"") -> 売上明細データ | F18: 全ての明細について売上計上の妥当性（収益認識基準の充足）を検討したコメントが提出されているか。 | G18: =COUNTIF('チェックポイント-問合せ・差戻し事例対応表'!$B:$B,A18) -> 15 | H18: =SUMPRODUCT(('チェックポイント-問合せ・差戻し事例対応表'!$B$2:$B$5000=A18)*('チェックポイント-問合せ・差戻し事例対応表'!$I$2:$I$5000<>"")/(COUNTIFS('チェックポイント-問合せ・差戻し事例対応表'!$B$2:$B$5000,'チェックポイント-問合せ・差戻し事例対応表'!$B$2:$B$5000,'チェックポイント-問合せ・差戻し事例対応表'!$I$2:$I$5000,'チェックポイント-問合せ・差戻し事例対応表'!$I$2:$I$5000)+('チェックポイント-問合せ・差戻し事例対応表'!$I$2:$I$5000=""))) -> 15 | I18: 29 | J18: =IFERROR(INDEX(レビュー指針!$D:$D,MATCH(I18,レビュー指針!$A:$A,0)),"") -> 成果物 | K18: =IFERROR(INDEX(レビュー指針!$E:$E,MATCH(I18,レビュー指針!$A:$A,0)),"") -> 1次レビュー | L18: =IFERROR(INDEX(レビュー指針!$H:$H,MATCH(I18,レビュー指針!$A:$A,0)),"") -> 全ての明細に対して売上計上の妥当性（収益認識基準を満たしているか）を検討したコメントが残されている | P18: Stage2精査 / 妥当性コメント / 自主点検QA由来 / 件数3 / 要文言整備
A19: 45 | B19: 8 | C19: =IFERROR(INDEX(自主点検項目!$B:$B,MATCH(B19,自主点検項目!$A:$A,0)),"") -> 売上のカットオフテスト | D19: 28 | E19: =IFERROR(INDEX(提出物!$D:$D,MATCH(D19,提出物!$A:$A,0)),"") -> 売上明細データ | F19: 提出された売上明細の合計が試算表・根拠資料と一致することが確認できるか。 | G19: =COUNTIF('チェックポイント-問合せ・差戻し事例対応表'!$B:$B,A19) -> 21 | H19: =SUMPRODUCT(('チェックポイント-問合せ・差戻し事例対応表'!$B$2:$B$5000=A19)*('チェックポイント-問合せ・差戻し事例対応表'!$I$2:$I$5000<>"")/(COUNTIFS('チェックポイント-問合せ・差戻し事例対応表'!$B$2:$B$5000,'チェックポイント-問合せ・差戻し事例対応表'!$B$2:$B$5000,'チェックポイント-問合せ・差戻し事例対応表'!$I$2:$I$5000,'チェックポイント-問合せ・差戻し事例対応表'!$I$2:$I$5000)+('チェックポイント-問合せ・差戻し事例対応表'!$I$2:$I$5000=""))) -> 18 | I19: 28 | J19: =IFERROR(INDEX(レビュー指針!$D:$D,MATCH(I19,レビュー指針!$A:$A,0)),"") -> 成果物 | K19: =IFERROR(INDEX(レビュー指針!$E:$E,MATCH(I19,レビュー指針!$A:$A,0)),"") -> 1次レビュー | L19: =IFERROR(INDEX(レビュー指針!$H:$H,MATCH(I19,レビュー指針!$A:$A,0)),"") -> 26年3月単月の全ての売上明細が提出されている（試算表との一致が確認できる） | P19: Stage2精査 / 網羅性・一致 / 自主点検QA由来 / 件数2 / 要文言整備
A20: 46 | B20: 8 | C20: =IFERROR(INDEX(自主点検項目!$B:$B,MATCH(B20,自主点検項目!$A:$A,0)),"") -> 売上のカットオフテスト | D20: 29 | E20: =IFERROR(INDEX(提出物!$D:$D,MATCH(D20,提出物!$A:$A,0)),"") -> データソース・抽出条件 | F20: 成果物の作成に用いたデータソースと抽出条件（手順）の記録（画面コピー等）が提出されているか。 | G20: =COUNTIF('チェックポイント-問合せ・差戻し事例対応表'!$B:$B,A20) -> 67 | H20: =SUMPRODUCT(('チェックポイント-問合せ・差戻し事例対応表'!$B$2:$B$5000=A20)*('チェックポイント-問合せ・差戻し事例対応表'!$I$2:$I$5000<>"")/(COUNTIFS('チェックポイント-問合せ・差戻し事例対応表'!$B$2:$B$5000,'チェックポイント-問合せ・差戻し事例対応表'!$B$2:$B$5000,'チェックポイント-問合せ・差戻し事例対応表'!$I$2:$I$5000,'チェックポイント-問合せ・差戻し事例対応表'!$I$2:$I$5000)+('チェックポイント-問合せ・差戻し事例対応表'!$I$2:$I$5000=""))) -> 63 | I20: 27 | J20: =IFERROR(INDEX(レビュー指針!$D:$D,MATCH(I20,レビュー指針!$A:$A,0)),"") -> 成果物 | K20: =IFERROR(INDEX(レビュー指針!$E:$E,MATCH(I20,レビュー指針!$A:$A,0)),"") -> 1次レビュー | L20: =IFERROR(INDEX(レビュー指針!$H:$H,MATCH(I20,レビュー指針!$A:$A,0)),"") -> データソースと抽出条件（手順）の記録が成果物として提出されている | P20: Stage2精査 / 複合問合せを分割（網羅性は別CPへ） / 自主点検QA由来 / 件数49 / 要文言整備
A21: 48 | B21: 8 | C21: =IFERROR(INDEX(自主点検項目!$B:$B,MATCH(B21,自主点検項目!$A:$A,0)),"") -> 売上のカットオフテスト | D21: 30 | E21: =IFERROR(INDEX(提出物!$D:$D,MATCH(D21,提出物!$A:$A,0)),"") -> 収益認識の根拠資料 | F21: 網羅性が確認できる情報（試算表との一致）が提出されているか。 | G21: =COUNTIF('チェックポイント-問合せ・差戻し事例対応表'!$B:$B,A21) -> 3 | H21: =SUMPRODUCT(('チェックポイント-問合せ・差戻し事例対応表'!$B$2:$B$5000=A21)*('チェックポイント-問合せ・差戻し事例対応表'!$I$2:$I$5000<>"")/(COUNTIFS('チェックポイント-問合せ・差戻し事例対応表'!$B$2:$B$5000,'チェックポイント-問合せ・差戻し事例対応表'!$B$2:$B$5000,'チェックポイント-問合せ・差戻し事例対応表'!$I$2:$I$5000,'チェックポイント-問合せ・差戻し事例対応表'!$I$2:$I$5000)+('チェックポイント-問合せ・差戻し事例対応表'!$I$2:$I$5000=""))) -> 3 | I21: 28 | J21: =IFERROR(INDEX(レビュー指針!$D:$D,MATCH(I21,レビュー指針!$A:$A,0)),"") -> 成果物 | K21: =IFERROR(INDEX(レビュー指針!$E:$E,MATCH(I21,レビュー指針!$A:$A,0)),"") -> 1次レビュー | L21: =IFERROR(INDEX(レビュー指針!$H:$H,MATCH(I21,レビュー指針!$A:$A,0)),"") -> 26年3月単月の全ての売上明細が提出されている（試算表との一致が確認できる） | P21: Stage2精査 / 網羅性 / 自主点検QA由来 / 件数2 / 要文言整備
A22: 49 | B22: 8 | C22: =IFERROR(INDEX(自主点検項目!$B:$B,MATCH(B22,自主点検項目!$A:$A,0)),"") -> 売上のカットオフテスト | D22: 30 | E22: =IFERROR(INDEX(提出物!$D:$D,MATCH(D22,提出物!$A:$A,0)),"") -> 収益認識の根拠資料 | F22: 全ての明細について売上計上の妥当性（収益認識基準の充足）を検討したコメントが提出されているか。 | G22: =COUNTIF('チェックポイント-問合せ・差戻し事例対応表'!$B:$B,A22) -> 2 | H22: =SUMPRODUCT(('チェックポイント-問合せ・差戻し事例対応表'!$B$2:$B$5000=A22)*('チェックポイント-問合せ・差戻し事例対応表'!$I$2:$I$5000<>"")/(COUNTIFS('チェックポイント-問合せ・差戻し事例対応表'!$B$2:$B$5000,'チェックポイント-問合せ・差戻し事例対応表'!$B$2:$B$5000,'チェックポイント-問合せ・差戻し事例対応表'!$I$2:$I$5000,'チェックポイント-問合せ・差戻し事例対応表'!$I$2:$I$5000)+('チェックポイント-問合せ・差戻し事例対応表'!$I$2:$I$5000=""))) -> 2 | I22: 29 | J22: =IFERROR(INDEX(レビュー指針!$D:$D,MATCH(I22,レビュー指針!$A:$A,0)),"") -> 成果物 | K22: =IFERROR(INDEX(レビュー指針!$E:$E,MATCH(I22,レビュー指針!$A:$A,0)),"") -> 1次レビュー | L22: =IFERROR(INDEX(レビュー指針!$H:$H,MATCH(I22,レビュー指針!$A:$A,0)),"") -> 全ての明細に対して売上計上の妥当性（収益認識基準を満たしているか）を検討したコメントが残されている | P22: Stage2精査 / 妥当性コメント / 自主点検QA由来 / 件数2 / 要文言整備
A23: 50 | B23: 8 | C23: =IFERROR(INDEX(自主点検項目!$B:$B,MATCH(B23,自主点検項目!$A:$A,0)),"") -> 売上のカットオフテスト | D23: 共通 | E23: =IFERROR(INDEX(提出物!$D:$D,MATCH(D23,提出物!$A:$A,0)),"") | F23: 全ての明細について売上計上の妥当性（収益認識基準の充足）を検討したコメントが提出されているか。 | G23: =COUNTIF('チェックポイント-問合せ・差戻し事例対応表'!$B:$B,A23) -> 15 | H23: =SUMPRODUCT(('チェックポイント-問合せ・差戻し事例対応表'!$B$2:$B$5000=A23)*('チェックポイント-問合せ・差戻し事例対応表'!$I$2:$I$5000<>"")/(COUNTIFS('チェックポイント-問合せ・差戻し事例対応表'!$B$2:$B$5000,'チェックポイント-問合せ・差戻し事例対応表'!$B$2:$B$5000,'チェックポイント-問合せ・差戻し事例対応表'!$I$2:$I$5000,'チェックポイント-問合せ・差戻し事例対応表'!$I$2:$I$5000)+('チェックポイント-問合せ・差戻し事例対応表'!$I$2:$I$5000=""))) -> 14 | I23: 29 | J23: =IFERROR(INDEX(レビュー指針!$D:$D,MATCH(I23,レビュー指針!$A:$A,0)),"") -> 成果物 | K23: =IFERROR(INDEX(レビュー指針!$E:$E,MATCH(I23,レビュー指針!$A:$A,0)),"") -> 1次レビュー | L23: =IFERROR(INDEX(レビュー指針!$H:$H,MATCH(I23,レビュー指針!$A:$A,0)),"") -> 全ての明細に対して売上計上の妥当性（収益認識基準を満たしているか）を検討したコメントが残されている | P23: Stage2精査 / 妥当性コメントチェック / 自主点検QA由来 / 件数5 / 要文言整備
A24: 52 | B24: 8 | C24: =IFERROR(INDEX(自主点検項目!$B:$B,MATCH(B24,自主点検項目!$A:$A,0)),"") -> 売上のカットオフテスト | D24: 共通 | E24: =IFERROR(INDEX(提出物!$D:$D,MATCH(D24,提出物!$A:$A,0)),"") | F24: 全ての明細について売上計上の妥当性（収益認識基準の充足）を検討したコメントが提出されているか。 | G24: =COUNTIF('チェックポイント-問合せ・差戻し事例対応表'!$B:$B,A24) -> 4 | H24: =SUMPRODUCT(('チェックポイント-問合せ・差戻し事例対応表'!$B$2:$B$5000=A24)*('チェックポイント-問合せ・差戻し事例対応表'!$I$2:$I$5000<>"")/(COUNTIFS('チェックポイント-問合せ・差戻し事例対応表'!$B$2:$B$5000,'チェックポイント-問合せ・差戻し事例対応表'!$B$2:$B$5000,'チェックポイント-問合せ・差戻し事例対応表'!$I$2:$I$5000,'チェックポイント-問合せ・差戻し事例対応表'!$I$2:$I$5000)+('チェックポイント-問合せ・差戻し事例対応表'!$I$2:$I$5000=""))) -> 4 | I24: 29 | J24: =IFERROR(INDEX(レビュー指針!$D:$D,MATCH(I24,レビュー指針!$A:$A,0)),"") -> 成果物 | K24: =IFERROR(INDEX(レビュー指針!$E:$E,MATCH(I24,レビュー指針!$A:$A,0)),"") -> 1次レビュー | L24: =IFERROR(INDEX(レビュー指針!$H:$H,MATCH(I24,レビュー指針!$A:$A,0)),"") -> 全ての明細に対して売上計上の妥当性（収益認識基準を満たしているか）を検討したコメントが残されている | P24: Stage2精査 / 妥当性コメント / 自主点検QA由来 / 件数2 / 要文言整備
A25: 53 | B25: 8 | C25: =IFERROR(INDEX(自主点検項目!$B:$B,MATCH(B25,自主点検項目!$A:$A,0)),"") -> 売上のカットオフテスト | D25: 共通 | E25: =IFERROR(INDEX(提出物!$D:$D,MATCH(D25,提出物!$A:$A,0)),"") | F25: 一定金額以上の取引について、数量・単価・計上日が確認できる根拠資料（注文書・請求書等）が提出されているか。 | G25: =COUNTIF('チェックポイント-問合せ・差戻し事例対応表'!$B:$B,A25) -> 5 | H25: =SUMPRODUCT(('チェックポイント-問合せ・差戻し事例対応表'!$B$2:$B$5000=A25)*('チェックポイント-問合せ・差戻し事例対応表'!$I$2:$I$5000<>"")/(COUNTIFS('チェックポイント-問合せ・差戻し事例対応表'!$B$2:$B$5000,'チェックポイント-問合せ・差戻し事例対応表'!$B$2:$B$5000,'チェックポイント-問合せ・差戻し事例対応表'!$I$2:$I$5000,'チェックポイント-問合せ・差戻し事例対応表'!$I$2:$I$5000)+('チェックポイント-問合せ・差戻し事例対応表'!$I$2:$I$5000=""))) -> 2 | I25: 30 | J25: =IFERROR(INDEX(レビュー指針!$D:$D,MATCH(I25,レビュー指針!$A:$A,0)),"") -> 根拠資料 | K25: =IFERROR(INDEX(レビュー指針!$E:$E,MATCH(I25,レビュー指針!$A:$A,0)),"") -> 1次レビュー | L25: =IFERROR(INDEX(レビュー指針!$H:$H,MATCH(I25,レビュー指針!$A:$A,0)),"") -> 1,000万円以上の取引について、根拠資料が提出されている | P25: Stage2精査 / 根拠資料 / 自主点検QA由来 / 件数2 / 要文言整備
A26: 56 | B26: 9 | C26: =IFERROR(INDEX(自主点検項目!$B:$B,MATCH(B26,自主点検項目!$A:$A,0)),"") -> 長期請負工事案件の洗い出し | D26: 32 | E26: =IFERROR(INDEX(提出物!$D:$D,MATCH(D26,提出物!$A:$A,0)),"") -> データソース・抽出条件 | F26: 成果物の作成に用いたデータソースと抽出条件（手順）の記録（画面コピー等）が提出されているか。 | G26: =COUNTIF('チェックポイント-問合せ・差戻し事例対応表'!$B:$B,A26) -> 6 | H26: =SUMPRODUCT(('チェックポイント-問合せ・差戻し事例対応表'!$B$2:$B$5000=A26)*('チェックポイント-問合せ・差戻し事例対応表'!$I$2:$I$5000<>"")/(COUNTIFS('チェックポイント-問合せ・差戻し事例対応表'!$B$2:$B$5000,'チェックポイント-問合せ・差戻し事例対応表'!$B$2:$B$5000,'チェックポイント-問合せ・差戻し事例対応表'!$I$2:$I$5000,'チェックポイント-問合せ・差戻し事例対応表'!$I$2:$I$5000)+('チェックポイント-問合せ・差戻し事例対応表'!$I$2:$I$5000=""))) -> 6 | I26: 38 | J26: =IFERROR(INDEX(レビュー指針!$D:$D,MATCH(I26,レビュー指針!$A:$A,0)),"") -> 成果物 | K26: =IFERROR(INDEX(レビュー指針!$E:$E,MATCH(I26,レビュー指針!$A:$A,0)),"") -> 1次レビュー | L26: =IFERROR(INDEX(レビュー指針!$H:$H,MATCH(I26,レビュー指針!$A:$A,0)),"") -> データソースと抽出条件（手順）の記録が成果物として提出されている | P26: Stage2精査 / データソース / 自主点検QA由来 / 件数4 / 要文言整備
A27: 57 | B27: 9 | C27: =IFERROR(INDEX(自主点検項目!$B:$B,MATCH(B27,自主点検項目!$A:$A,0)),"") -> 長期請負工事案件の洗い出し | D27: 共通 | E27: =IFERROR(INDEX(提出物!$D:$D,MATCH(D27,提出物!$A:$A,0)),"") | F27: 成果物の作成に用いたデータソースと抽出条件（手順）の記録（画面コピー等）が提出されているか。 | G27: =COUNTIF('チェックポイント-問合せ・差戻し事例対応表'!$B:$B,A27) -> 3 | H27: =SUMPRODUCT(('チェックポイント-問合せ・差戻し事例対応表'!$B$2:$B$5000=A27)*('チェックポイント-問合せ・差戻し事例対応表'!$I$2:$I$5000<>"")/(COUNTIFS('チェックポイント-問合せ・差戻し事例対応表'!$B$2:$B$5000,'チェックポイント-問合せ・差戻し事例対応表'!$B$2:$B$5000,'チェックポイント-問合せ・差戻し事例対応表'!$I$2:$I$5000,'チェックポイント-問合せ・差戻し事例対応表'!$I$2:$I$5000)+('チェックポイント-問合せ・差戻し事例対応表'!$I$2:$I$5000=""))) -> 3 | I27: 38 | J27: =IFERROR(INDEX(レビュー指針!$D:$D,MATCH(I27,レビュー指針!$A:$A,0)),"") -> 成果物 | K27: =IFERROR(INDEX(レビュー指針!$E:$E,MATCH(I27,レビュー指針!$A:$A,0)),"") -> 1次レビュー | L27: =IFERROR(INDEX(レビュー指針!$H:$H,MATCH(I27,レビュー指針!$A:$A,0)),"") -> データソースと抽出条件（手順）の記録が成果物として提出されている | P27: Stage2精査 / データソース / 自主点検QA由来 / 件数3 / 要文言整備
A28: 58 | B28: 9 | C28: =IFERROR(INDEX(自主点検項目!$B:$B,MATCH(B28,自主点検項目!$A:$A,0)),"") -> 長期請負工事案件の洗い出し | D28: 共通 | E28: =IFERROR(INDEX(提出物!$D:$D,MATCH(D28,提出物!$A:$A,0)),"") | F28: 網羅性が確認できる情報（2026年3月試算表・PKGの進行基準売上との一致）が提出されているか。 | G28: =COUNTIF('チェックポイント-問合せ・差戻し事例対応表'!$B:$B,A28) -> 3 | H28: =SUMPRODUCT(('チェックポイント-問合せ・差戻し事例対応表'!$B$2:$B$5000=A28)*('チェックポイント-問合せ・差戻し事例対応表'!$I$2:$I$5000<>"")/(COUNTIFS('チェックポイント-問合せ・差戻し事例対応表'!$B$2:$B$5000,'チェックポイント-問合せ・差戻し事例対応表'!$B$2:$B$5000,'チェックポイント-問合せ・差戻し事例対応表'!$I$2:$I$5000,'チェックポイント-問合せ・差戻し事例対応表'!$I$2:$I$5000)+('チェックポイント-問合せ・差戻し事例対応表'!$I$2:$I$5000=""))) -> 3 | I28: 39 | J28: =IFERROR(INDEX(レビュー指針!$D:$D,MATCH(I28,レビュー指針!$A:$A,0)),"") -> 成果物 | K28: =IFERROR(INDEX(レビュー指針!$E:$E,MATCH(I28,レビュー指針!$A:$A,0)),"") -> 1次レビュー | L28: =IFERROR(INDEX(レビュー指針!$H:$H,MATCH(I28,レビュー指針!$A:$A,0)),"") -> 網羅性が確認できる情報が記載又は提出されている（例：PKGの進行基準売上との一致） | P28: Stage2精査 / 網羅性 / 自主点検QA由来 / 件数2 / 要文言整備
A29: 59 | B29: 9 | C29: =IFERROR(INDEX(自主点検項目!$B:$B,MATCH(B29,自主点検項目!$A:$A,0)),"") -> 長期請負工事案件の洗い出し | D29: 共通 | E29: =IFERROR(INDEX(提出物!$D:$D,MATCH(D29,提出物!$A:$A,0)),"") | F29: 全ての取引について進行基準の適用可否に関する判断根拠が記載されているか。 | G29: =COUNTIF('チェックポイント-問合せ・差戻し事例対応表'!$B:$B,A29) -> 4 | H29: =SUMPRODUCT(('チェックポイント-問合せ・差戻し事例対応表'!$B$2:$B$5000=A29)*('チェックポイント-問合せ・差戻し事例対応表'!$I$2:$I$5000<>"")/(COUNTIFS('チェックポイント-問合せ・差戻し事例対応表'!$B$2:$B$5000,'チェックポイント-問合せ・差戻し事例対応表'!$B$2:$B$5000,'チェックポイント-問合せ・差戻し事例対応表'!$I$2:$I$5000,'チェックポイント-問合せ・差戻し事例対応表'!$I$2:$I$5000)+('チェックポイント-問合せ・差戻し事例対応表'!$I$2:$I$5000=""))) -> 4 | I29: 40 | J29: =IFERROR(INDEX(レビュー指針!$D:$D,MATCH(I29,レビュー指針!$A:$A,0)),"") -> 成果物 | K29: =IFERROR(INDEX(レビュー指針!$E:$E,MATCH(I29,レビュー指針!$A:$A,0)),"") -> 1次レビュー | L29: =IFERROR(INDEX(レビュー指針!$H:$H,MATCH(I29,レビュー指針!$A:$A,0)),"") -> 全ての取引について進行基準の適用可否に関する判断根拠が記載されている | P29: Stage2精査 / 判断根拠 / 自主点検QA由来 / 件数2 / 要文言整備
A30: 60 | B30: 10 | C30: =IFERROR(INDEX(自主点検項目!$B:$B,MATCH(B30,自主点検項目!$A:$A,0)),"") -> 実行予算の取得・確認 | D30: 35 | E30: =IFERROR(INDEX(提出物!$D:$D,MATCH(D30,提出物!$A:$A,0)),"") -> データソース・抽出条件 | F30: 成果物の作成に用いたデータソースと抽出条件（手順）の記録（画面コピー等）が提出されているか。 | G30: =COUNTIF('チェックポイント-問合せ・差戻し事例対応表'!$B:$B,A30) -> 8 | H30: =SUMPRODUCT(('チェックポイント-問合せ・差戻し事例対応表'!$B$2:$B$5000=A30)*('チェックポイント-問合せ・差戻し事例対応表'!$I$2:$I$5000<>"")/(COUNTIFS('チェックポイント-問合せ・差戻し事例対応表'!$B$2:$B$5000,'チェックポイント-問合せ・差戻し事例対応表'!$B$2:$B$5000,'チェックポイント-問合せ・差戻し事例対応表'!$I$2:$I$5000,'チェックポイント-問合せ・差戻し事例対応表'!$I$2:$I$5000)+('チェックポイント-問合せ・差戻し事例対応表'!$I$2:$I$5000=""))) -> 8 | I30: 44 | J30: =IFERROR(INDEX(レビュー指針!$D:$D,MATCH(I30,レビュー指針!$A:$A,0)),"") -> 成果物 | K30: =IFERROR(INDEX(レビュー指針!$E:$E,MATCH(I30,レビュー指針!$A:$A,0)),"") -> 1次レビュー | L30: =IFERROR(INDEX(レビュー指針!$H:$H,MATCH(I30,レビュー指針!$A:$A,0)),"") -> データソースと抽出条件（手順）の記録が成果物として提出されている | P30: Stage2精査 / 複合問合せを分割（網羅性は別CPへ） / 自主点検QA由来 / 件数5 / 要文言整備
A31: 62 | B31: 11 | C31: =IFERROR(INDEX(自主点検項目!$B:$B,MATCH(B31,自主点検項目!$A:$A,0)),"") -> 材料費の実際発生原価の確認 | D31: 共通 | E31: =IFERROR(INDEX(提出物!$D:$D,MATCH(D31,提出物!$A:$A,0)),"") | F31: 成果物の作成に用いたデータソースと抽出条件（手順）の記録（画面コピー等）が提出されているか。 | G31: =COUNTIF('チェックポイント-問合せ・差戻し事例対応表'!$B:$B,A31) -> 6 | H31: =SUMPRODUCT(('チェックポイント-問合せ・差戻し事例対応表'!$B$2:$B$5000=A31)*('チェックポイント-問合せ・差戻し事例対応表'!$I$2:$I$5000<>"")/(COUNTIFS('チェックポイント-問合せ・差戻し事例対応表'!$B$2:$B$5000,'チェックポイント-問合せ・差戻し事例対応表'!$B$2:$B$5000,'チェックポイント-問合せ・差戻し事例対応表'!$I$2:$I$5000,'チェックポイント-問合せ・差戻し事例対応表'!$I$2:$I$5000)+('チェックポイント-問合せ・差戻し事例対応表'!$I$2:$I$5000=""))) -> 6 | I31: 49 | J31: =IFERROR(INDEX(レビュー指針!$D:$D,MATCH(I31,レビュー指針!$A:$A,0)),"") -> 成果物 | K31: =IFERROR(INDEX(レビュー指針!$E:$E,MATCH(I31,レビュー指針!$A:$A,0)),"") -> 1次レビュー | L31: =IFERROR(INDEX(レビュー指針!$H:$H,MATCH(I31,レビュー指針!$A:$A,0)),"") -> データソースと抽出条件（手順）の記録が成果物として提出されている | P31: Stage2精査 / データソース / 自主点検QA由来 / 件数5 / 要文言整備
A32: 63 | B32: 11 | C32: =IFERROR(INDEX(自主点検項目!$B:$B,MATCH(B32,自主点検項目!$A:$A,0)),"") -> 材料費の実際発生原価の確認 | D32: 共通 | E32: =IFERROR(INDEX(提出物!$D:$D,MATCH(D32,提出物!$A:$A,0)),"") | F32: 購買データ・入出庫データ・原価明細を比較し整合性が確認できているか。 | G32: =COUNTIF('チェックポイント-問合せ・差戻し事例対応表'!$B:$B,A32) -> 3 | H32: =SUMPRODUCT(('チェックポイント-問合せ・差戻し事例対応表'!$B$2:$B$5000=A32)*('チェックポイント-問合せ・差戻し事例対応表'!$I$2:$I$5000<>"")/(COUNTIFS('チェックポイント-問合せ・差戻し事例対応表'!$B$2:$B$5000,'チェックポイント-問合せ・差戻し事例対応表'!$B$2:$B$5000,'チェックポイント-問合せ・差戻し事例対応表'!$I$2:$I$5000,'チェックポイント-問合せ・差戻し事例対応表'!$I$2:$I$5000)+('チェックポイント-問合せ・差戻し事例対応表'!$I$2:$I$5000=""))) -> 2 | I32: 51 | J32: =IFERROR(INDEX(レビュー指針!$D:$D,MATCH(I32,レビュー指針!$A:$A,0)),"") -> 成果物 | K32: =IFERROR(INDEX(レビュー指針!$E:$E,MATCH(I32,レビュー指針!$A:$A,0)),"") -> 1次レビュー | L32: =IFERROR(INDEX(レビュー指針!$H:$H,MATCH(I32,レビュー指針!$A:$A,0)),"") -> 購買データ、入出庫データ、原価明細を比較し整合性を確認できている | P32: Stage2精査 / 整合性 / 自主点検QA由来 / 件数2 / 要文言整備
A33: 64 | B33: 11 | C33: =IFERROR(INDEX(自主点検項目!$B:$B,MATCH(B33,自主点検項目!$A:$A,0)),"") -> 材料費の実際発生原価の確認 | D33: 共通 | E33: =IFERROR(INDEX(提出物!$D:$D,MATCH(D33,提出物!$A:$A,0)),"") | F33: 網羅性が確認できる情報（試算表との一致）が提出されているか。 | G33: =COUNTIF('チェックポイント-問合せ・差戻し事例対応表'!$B:$B,A33) -> 3 | H33: =SUMPRODUCT(('チェックポイント-問合せ・差戻し事例対応表'!$B$2:$B$5000=A33)*('チェックポイント-問合せ・差戻し事例対応表'!$I$2:$I$5000<>"")/(COUNTIFS('チェックポイント-問合せ・差戻し事例対応表'!$B$2:$B$5000,'チェックポイント-問合せ・差戻し事例対応表'!$B$2:$B$5000,'チェックポイント-問合せ・差戻し事例対応表'!$I$2:$I$5000,'チェックポイント-問合せ・差戻し事例対応表'!$I$2:$I$5000)+('チェックポイント-問合せ・差戻し事例対応表'!$I$2:$I$5000=""))) -> 3 | I33: 50 | J33: =IFERROR(INDEX(レビュー指針!$D:$D,MATCH(I33,レビュー指針!$A:$A,0)),"") -> 成果物 | K33: =IFERROR(INDEX(レビュー指針!$E:$E,MATCH(I33,レビュー指針!$A:$A,0)),"") -> 1次レビュー | L33: =IFERROR(INDEX(レビュー指針!$H:$H,MATCH(I33,レビュー指針!$A:$A,0)),"") -> 網羅性が確認できる情報が記載又は提出されている（試算表との一致を確認できる） | P33: Stage2精査 / 網羅性 / 自主点検QA由来 / 件数2 / 要文言整備
A34: 65 | B34: 12 | C34: =IFERROR(INDEX(自主点検項目!$B:$B,MATCH(B34,自主点検項目!$A:$A,0)),"") -> 進捗率の算定根拠の確認 | D34: 41 | E34: =IFERROR(INDEX(提出物!$D:$D,MATCH(D34,提出物!$A:$A,0)),"") -> データソース・抽出条件 | F34: 成果物の作成に用いたデータソースと抽出条件（手順）の記録（画面コピー等）が提出されているか。 | G34: =COUNTIF('チェックポイント-問合せ・差戻し事例対応表'!$B:$B,A34) -> 9 | H34: =SUMPRODUCT(('チェックポイント-問合せ・差戻し事例対応表'!$B$2:$B$5000=A34)*('チェックポイント-問合せ・差戻し事例対応表'!$I$2:$I$5000<>"")/(COUNTIFS('チェックポイント-問合せ・差戻し事例対応表'!$B$2:$B$5000,'チェックポイント-問合せ・差戻し事例対応表'!$B$2:$B$5000,'チェックポイント-問合せ・差戻し事例対応表'!$I$2:$I$5000,'チェックポイント-問合せ・差戻し事例対応表'!$I$2:$I$5000)+('チェックポイント-問合せ・差戻し事例対応表'!$I$2:$I$5000=""))) -> 9 | I34: 55 | J34: =IFERROR(INDEX(レビュー指針!$D:$D,MATCH(I34,レビュー指針!$A:$A,0)),"") -> 成果物 | K34: =IFERROR(INDEX(レビュー指針!$E:$E,MATCH(I34,レビュー指針!$A:$A,0)),"") -> 1次レビュー | L34: =IFERROR(INDEX(レビュー指針!$H:$H,MATCH(I34,レビュー指針!$A:$A,0)),"") -> データソースと抽出条件（手順）の記録が成果物として提出されている | P34: Stage2精査 / 複合問合せを分割（網羅性は別CPへ） / 自主点検QA由来 / 件数8 / 要文言整備
A35: 66 | B35: 13 | C35: =IFERROR(INDEX(自主点検項目!$B:$B,MATCH(B35,自主点検項目!$A:$A,0)),"") -> 経費の実際発生原価の確認 | D35: 43 | E35: =IFERROR(INDEX(提出物!$D:$D,MATCH(D35,提出物!$A:$A,0)),"") -> データソース・抽出条件 | F35: 成果物の作成に用いたデータソースと抽出条件（手順）の記録（画面コピー等）が提出されているか。 | G35: =COUNTIF('チェックポイント-問合せ・差戻し事例対応表'!$B:$B,A35) -> 6 | H35: =SUMPRODUCT(('チェックポイント-問合せ・差戻し事例対応表'!$B$2:$B$5000=A35)*('チェックポイント-問合せ・差戻し事例対応表'!$I$2:$I$5000<>"")/(COUNTIFS('チェックポイント-問合せ・差戻し事例対応表'!$B$2:$B$5000,'チェックポイント-問合せ・差戻し事例対応表'!$B$2:$B$5000,'チェックポイント-問合せ・差戻し事例対応表'!$I$2:$I$5000,'チェックポイント-問合せ・差戻し事例対応表'!$I$2:$I$5000)+('チェックポイント-問合せ・差戻し事例対応表'!$I$2:$I$5000=""))) -> 6 | I35: 62 | J35: =IFERROR(INDEX(レビュー指針!$D:$D,MATCH(I35,レビュー指針!$A:$A,0)),"") -> 成果物 | K35: =IFERROR(INDEX(レビュー指針!$E:$E,MATCH(I35,レビュー指針!$A:$A,0)),"") -> 1次レビュー | L35: =IFERROR(INDEX(レビュー指針!$H:$H,MATCH(I35,レビュー指針!$A:$A,0)),"") -> データソースと抽出条件（手順）の記録が成果物として提出されている | P35: Stage2精査 / 複合問合せを分割（網羅性は別CPへ） / 自主点検QA由来 / 件数6 / 要文言整備
A36: 67 | B36: 14 | C36: =IFERROR(INDEX(自主点検項目!$B:$B,MATCH(B36,自主点検項目!$A:$A,0)),"") -> 原価振替取引の要因説明 | D36: 46 | E36: =IFERROR(INDEX(提出物!$D:$D,MATCH(D36,提出物!$A:$A,0)),"") -> データソース・抽出基準/手順 | F36: 成果物の作成に用いたデータソースと抽出条件（手順）の記録（画面コピー等）が提出されているか。 | G36: =COUNTIF('チェックポイント-問合せ・差戻し事例対応表'!$B:$B,A36) -> 5 | H36: =SUMPRODUCT(('チェックポイント-問合せ・差戻し事例対応表'!$B$2:$B$5000=A36)*('チェックポイント-問合せ・差戻し事例対応表'!$I$2:$I$5000<>"")/(COUNTIFS('チェックポイント-問合せ・差戻し事例対応表'!$B$2:$B$5000,'チェックポイント-問合せ・差戻し事例対応表'!$B$2:$B$5000,'チェックポイント-問合せ・差戻し事例対応表'!$I$2:$I$5000,'チェックポイント-問合せ・差戻し事例対応表'!$I$2:$I$5000)+('チェックポイント-問合せ・差戻し事例対応表'!$I$2:$I$5000=""))) -> 5 | I36: 67 | J36: =IFERROR(INDEX(レビュー指針!$D:$D,MATCH(I36,レビュー指針!$A:$A,0)),"") -> 成果物 | K36: =IFERROR(INDEX(レビュー指針!$E:$E,MATCH(I36,レビュー指針!$A:$A,0)),"") -> 1次レビュー | L36: =IFERROR(INDEX(レビュー指針!$H:$H,MATCH(I36,レビュー指針!$A:$A,0)),"") -> データソースと抽出条件（手順）の記録が成果物として提出されている | P36: Stage2精査 / データソース / 自主点検QA由来 / 件数5 / 要文言整備
A37: 68 | B37: 15 | C37: =IFERROR(INDEX(自主点検項目!$B:$B,MATCH(B37,自主点検項目!$A:$A,0)),"") -> 低粗利案件の分析 | D37: 50 | E37: =IFERROR(INDEX(提出物!$D:$D,MATCH(D37,提出物!$A:$A,0)),"") -> データソース・抽出条件 | F37: 成果物の作成に用いたデータソースと抽出条件（手順）の記録（画面コピー等）が提出されているか。 | G37: =COUNTIF('チェックポイント-問合せ・差戻し事例対応表'!$B:$B,A37) -> 7 | H37: =SUMPRODUCT(('チェックポイント-問合せ・差戻し事例対応表'!$B$2:$B$5000=A37)*('チェックポイント-問合せ・差戻し事例対応表'!$I$2:$I$5000<>"")/(COUNTIFS('チェックポイント-問合せ・差戻し事例対応表'!$B$2:$B$5000,'チェックポイント-問合せ・差戻し事例対応表'!$B$2:$B$5000,'チェックポイント-問合せ・差戻し事例対応表'!$I$2:$I$5000,'チェックポイント-問合せ・差戻し事例対応表'!$I$2:$I$5000)+('チェックポイント-問合せ・差戻し事例対応表'!$I$2:$I$5000=""))) -> 7 | I37: 72 | J37: =IFERROR(INDEX(レビュー指針!$D:$D,MATCH(I37,レビュー指針!$A:$A,0)),"") -> 成果物 | K37: =IFERROR(INDEX(レビュー指針!$E:$E,MATCH(I37,レビュー指針!$A:$A,0)),"") -> 1次レビュー | L37: =IFERROR(INDEX(レビュー指針!$H:$H,MATCH(I37,レビュー指針!$A:$A,0)),"") -> データソースと抽出条件（手順）の記録が成果物として提出されている | P37: Stage2精査 / 複合問合せを分割（網羅性は別CPへ） / 自主点検QA由来 / 件数3 / 要文言整備
A38: 70 | B38: 18 | C38: =IFERROR(INDEX(自主点検項目!$B:$B,MATCH(B38,自主点検項目!$A:$A,0)),"") -> 各費用月次推移分析 | D38: 53 | E38: =IFERROR(INDEX(提出物!$D:$D,MATCH(D38,提出物!$A:$A,0)),"") -> 販管費の月次推移データ | F38: 販管費科目の月次推移表・グラフが作成され、絶対額・変化率の両面で必要箇所にコメントがあるか。 | G38: =COUNTIF('チェックポイント-問合せ・差戻し事例対応表'!$B:$B,A38) -> 27 | H38: =SUMPRODUCT(('チェックポイント-問合せ・差戻し事例対応表'!$B$2:$B$5000=A38)*('チェックポイント-問合せ・差戻し事例対応表'!$I$2:$I$5000<>"")/(COUNTIFS('チェックポイント-問合せ・差戻し事例対応表'!$B$2:$B$5000,'チェックポイント-問合せ・差戻し事例対応表'!$B$2:$B$5000,'チェックポイント-問合せ・差戻し事例対応表'!$I$2:$I$5000,'チェックポイント-問合せ・差戻し事例対応表'!$I$2:$I$5000)+('チェックポイント-問合せ・差戻し事例対応表'!$I$2:$I$5000=""))) -> 27 | I38: 81 | J38: =IFERROR(INDEX(レビュー指針!$D:$D,MATCH(I38,レビュー指針!$A:$A,0)),"") -> 成果物 | K38: =IFERROR(INDEX(レビュー指針!$E:$E,MATCH(I38,レビュー指針!$A:$A,0)),"") -> 1次レビュー | L38: =IFERROR(INDEX(レビュー指針!$H:$H,MATCH(I38,レビュー指針!$A:$A,0)),"") -> 25年4月～26年3月の科目毎の月次推移表及びグラフが作成されている | P38: Stage2精査 / 推移表作成チェック / 自主点検QA由来 / 件数11 / 要文言整備
A39: 77 | B39: 18 | C39: =IFERROR(INDEX(自主点検項目!$B:$B,MATCH(B39,自主点検項目!$A:$A,0)),"") -> 各費用月次推移分析 | D39: 54 | E39: =IFERROR(INDEX(提出物!$D:$D,MATCH(D39,提出物!$A:$A,0)),"") -> データソース・抽出条件 | F39: 成果物の作成に用いたデータソースと抽出条件（手順）の記録（画面コピー等）が提出されているか。 | G39: =COUNTIF('チェックポイント-問合せ・差戻し事例対応表'!$B:$B,A39) -> 77 | H39: =SUMPRODUCT(('チェックポイント-問合せ・差戻し事例対応表'!$B$2:$B$5000=A39)*('チェックポイント-問合せ・差戻し事例対応表'!$I$2:$I$5000<>"")/(COUNTIFS('チェックポイント-問合せ・差戻し事例対応表'!$B$2:$B$5000,'チェックポイント-問合せ・差戻し事例対応表'!$B$2:$B$5000,'チェックポイント-問合せ・差戻し事例対応表'!$I$2:$I$5000,'チェックポイント-問合せ・差戻し事例対応表'!$I$2:$I$5000)+('チェックポイント-問合せ・差戻し事例対応表'!$I$2:$I$5000=""))) -> 73 | I39: 79 | J39: =IFERROR(INDEX(レビュー指針!$D:$D,MATCH(I39,レビュー指針!$A:$A,0)),"") -> 成果物 | K39: =IFERROR(INDEX(レビュー指針!$E:$E,MATCH(I39,レビュー指針!$A:$A,0)),"") -> 1次レビュー | L39: =IFERROR(INDEX(レビュー指針!$H:$H,MATCH(I39,レビュー指針!$A:$A,0)),"") -> データソースと抽出条件（手順）の記録が成果物として提出されている | P39: Stage2精査 / 複合問合せを分割（網羅性は別CPへ） / 自主点検QA由来 / 件数65 / 要文言整備
A40: 83 | B40: 18 | C40: =IFERROR(INDEX(自主点検項目!$B:$B,MATCH(B40,自主点検項目!$A:$A,0)),"") -> 各費用月次推移分析 | D40: 55 | E40: =IFERROR(INDEX(提出物!$D:$D,MATCH(D40,提出物!$A:$A,0)),"") -> 著しい増加の根拠資料 | F40: 網羅性が確認できる情報が記載又は提出されている | G40: =COUNTIF('チェックポイント-問合せ・差戻し事例対応表'!$B:$B,A40) -> 8 | H40: =SUMPRODUCT(('チェックポイント-問合せ・差戻し事例対応表'!$B$2:$B$5000=A40)*('チェックポイント-問合せ・差戻し事例対応表'!$I$2:$I$5000<>"")/(COUNTIFS('チェックポイント-問合せ・差戻し事例対応表'!$B$2:$B$5000,'チェックポイント-問合せ・差戻し事例対応表'!$B$2:$B$5000,'チェックポイント-問合せ・差戻し事例対応表'!$I$2:$I$5000,'チェックポイント-問合せ・差戻し事例対応表'!$I$2:$I$5000)+('チェックポイント-問合せ・差戻し事例対応表'!$I$2:$I$5000=""))) -> 8 | I40: 80 | J40: =IFERROR(INDEX(レビュー指針!$D:$D,MATCH(I40,レビュー指針!$A:$A,0)),"") -> 成果物 | K40: =IFERROR(INDEX(レビュー指針!$E:$E,MATCH(I40,レビュー指針!$A:$A,0)),"") -> 1次レビュー | L40: =IFERROR(INDEX(レビュー指針!$H:$H,MATCH(I40,レビュー指針!$A:$A,0)),"") -> 網羅性が確認できる情報が記載又は提出されている | P40: Stage2精査(裾野・要確認) / 自主点検QA由来 / 件数2 / 要文言整備
...

Sheet 問合せ・差戻し事例
A1: No | B1: ソース | C1: 元No | D1: 会社管理番号 | E1: 会社名 | F1: ユニット | G1: 自主点検項目No | H1: 問合せ事項 | I1: CP化判定
A2: 1 | B2: 自主点検QA | C2: 23-1 | D2: 230103 | E2: =IFERROR(INDEX(会社マスタ!$B:$B,MATCH(D2,会社マスタ!$A:$A,0)),"") -> 竹中運輸(株) | F2: =IFERROR(INDEX(会社マスタ!$C:$C,MATCH(D2,会社マスタ!$A:$A,0)),"") -> エア・ウォーター東日本(株) | G2: 26 | H2: ・賞与引当金を計上する際に、繰入金額の計算資料の送付をお願いします | I2: 未判定
A3: 2 | B3: 自主点検QA | C3: 23-2 | D3: 230700 | E3: =IFERROR(INDEX(会社マスタ!$B:$B,MATCH(D3,会社マスタ!$A:$A,0)),"") -> 亀山液酸(株) | F3: =IFERROR(INDEX(会社マスタ!$C:$C,MATCH(D3,会社マスタ!$A:$A,0)),"") -> エア・ウォーター東日本(株) | G3: 26 | H3: ・賞与引当金を計上する際に、繰入金額の計算資料の送付をお願いします | I3: 未判定
A4: 3 | B4: 自主点検QA | C4: 23-3 | D4: 230900 | E4: =IFERROR(INDEX(会社マスタ!$B:$B,MATCH(D4,会社マスタ!$A:$A,0)),"") -> 静岡液酸(株) | F4: =IFERROR(INDEX(会社マスタ!$C:$C,MATCH(D4,会社マスタ!$A:$A,0)),"") -> エア・ウォーター東日本(株) | G4: 26 | H4: ・賞与引当金を計上する際に、繰入金額の計算資料の送付をお願いします | I4: 未判定
A5: 4 | B5: 自主点検QA | C5: 23-4 | D5: 231000 | E5: =IFERROR(INDEX(会社マスタ!$B:$B,MATCH(D5,会社マスタ!$A:$A,0)),"") -> 東海液酸(株) | F5: =IFERROR(INDEX(会社マスタ!$C:$C,MATCH(D5,会社マスタ!$A:$A,0)),"") -> エア・ウォーター東日本(株) | G5: 26 | H5: ・賞与引当金を計上する際に、繰入金額の計算資料の送付をお願いします | I5: 未判定
A6: 5 | B6: 自主点検QA | C6: 23-5 | D6: 231400 | E6: =IFERROR(INDEX(会社マスタ!$B:$B,MATCH(D6,会社マスタ!$A:$A,0)),"") -> (株)元気 | F6: =IFERROR(INDEX(会社マスタ!$C:$C,MATCH(D6,会社マスタ!$A:$A,0)),"") -> エア・ウォーター東日本(株) | G6: 26 | H6: ・網羅性が確認できる資料（試算表との一致確認）の送付をお願いします ・賞与引当金を計上する際に、繰入金額の計算資料の送付をお願いします | I6: 未判定
A7: 6 | B7: 自主点検QA | C7: 23-6 | D7: 230900 | E7: =IFERROR(INDEX(会社マスタ!$B:$B,MATCH(D7,会社マスタ!$A:$A,0)),"") -> 静岡液酸(株) | F7: =IFERROR(INDEX(会社マスタ!$C:$C,MATCH(D7,会社マスタ!$A:$A,0)),"") -> エア・ウォーター東日本(株) | G7: 8 | H7: ・1,000万円以上の売上の根拠として契約書を提出いただいておりますが単価のみの記載のため請求額の根拠資料となる数量が分かる資料の送付をお願いします | I7: 未判定
A8: 7 | B8: 自主点検QA | C8: 23-7 | D8: 231000 | E8: =IFERROR(INDEX(会社マスタ!$B:$B,MATCH(D8,会社マスタ!$A:$A,0)),"") -> 東海液酸(株) | F8: =IFERROR(INDEX(会社マスタ!$C:$C,MATCH(D8,会社マスタ!$A:$A,0)),"") -> エア・ウォーター東日本(株) | G8: 8 | H8: ・網羅性が確認できる資料（試算表との一致確認）の送付をお願いします ・1,000万円以上の売上が計上されているため、該当取引について収益認識の根拠となる資料の送付をお願いします | I8: 未判定
A9: 8 | B9: 自主点検QA | C9: 23-8 | D9: 230101 | E9: =IFERROR(INDEX(会社マスタ!$B:$B,MATCH(D9,会社マスタ!$A:$A,0)),"") -> (株)環境技術センター | F9: =IFERROR(INDEX(会社マスタ!$C:$C,MATCH(D9,会社マスタ!$A:$A,0)),"") -> エア・ウォーター東日本(株) | G9: 5 | H9: ・データソース及び抽出条件が分かる資料（抽出する際の条件を記載した画面スクショなど）の提出をお願い出来ますでしょうか。 ・マイナスの売上計上の妥当性を確認するため、全てのエントリーに対してマイナス売上理由のコメント及び、各マイナスの売上計上に対してそこまで至った経緯・取り消しの妥当性を裏付けるの証跡の提出をお願い出来ますでしょうか。 | I9: 未判定
A10: 9 | B10: 自主点検QA | C10: 23-9 | D10: 230103 | E10: =IFERROR(INDEX(会社マスタ!$B:$B,MATCH(D10,会社マスタ!$A:$A,0)),"") -> 竹中運輸(株) | F10: =IFERROR(INDEX(会社マスタ!$C:$C,MATCH(D10,会社マスタ!$A:$A,0)),"") -> エア・ウォーター東日本(株) | G10: 5 | H10: ・データソース及び抽出条件が分かる資料（抽出する際の条件を記載した画面スクショなど）の提出をお願い出来ますでしょうか。 | I10: 未判定
A11: 10 | B11: 自主点検QA | C11: 23-10 | D11: 230700 | E11: =IFERROR(INDEX(会社マスタ!$B:$B,MATCH(D11,会社マスタ!$A:$A,0)),"") -> 亀山液酸(株) | F11: =IFERROR(INDEX(会社マスタ!$C:$C,MATCH(D11,会社マスタ!$A:$A,0)),"") -> エア・ウォーター東日本(株) | G11: 5 | H11: ・網羅性及び売上伝票/明細と試算表の整合性を確認するため、25年4月~26年3月の全ての売上明細（マイナス含む）の提出をお願い出来ますでしょうか ・マイナスの売上計上の妥当性を確認するため、全てのエントリーに対してマイナス売上理由のコメント及び、各マイナスの売上計上に対してそこまで至った経緯・取り消しの妥当性を裏付けるの証跡の提出をお願い出来ますでしょうか。 | I11: 未判定
A12: 11 | B12: 自主点検QA | C12: 23-11 | D12: 230900 | E12: =IFERROR(INDEX(会社マスタ!$B:$B,MATCH(D12,会社マスタ!$A:$A,0)),"") -> 静岡液酸(株) | F12: =IFERROR(INDEX(会社マスタ!$C:$C,MATCH(D12,会社マスタ!$A:$A,0)),"") -> エア・ウォーター東日本(株) | G12: 5 | H12: ・網羅性及び売上伝票/明細と試算表の整合性を確認するため、25年4月~26年3月の全ての売上明細（マイナス含む）の提出をお願い出来ますでしょうか ・マイナスの売上計上の妥当性を確認するため、全てのエントリーに対してマイナス売上理由のコメント及び、各マイナスの売上計上に対してそこまで至った経緯・取り消しの妥当性を裏付けるの証跡の提出をお願い出来ますでしょうか。 | I12: 未判定
A13: 12 | B13: 自主点検QA | C13: 23-12 | D13: 231000 | E13: =IFERROR(INDEX(会社マスタ!$B:$B,MATCH(D13,会社マスタ!$A:$A,0)),"") -> 東海液酸(株) | F13: =IFERROR(INDEX(会社マスタ!$C:$C,MATCH(D13,会社マスタ!$A:$A,0)),"") -> エア・ウォーター東日本(株) | G13: 5 | H13: ・網羅性及び売上伝票/明細と試算表の整合性を確認するため、25年4月~26年3月の全ての売上明細（マイナス含む）の提出をお願い出来ますでしょうか ・マイナスの売上計上の妥当性を確認するため、全てのエントリーに対してマイナス売上理由のコメント及び、各マイナスの売上計上に対してそこまで至った経緯・取り消しの妥当性を裏付けるの証跡の提出をお願い出来ますでしょうか。 | I13: 未判定
